Workbook

Sheet Julho-2022
A1: Papel | B1: Descrição | C1: Grupo | D1: Gramatura (g/m²) | E1: Custo ($/t)|Valor REAL
A2: 0 | B2: OUTROS | C2: 20-40-60 | D2: 1 | E2: 1
A3: BRN 056 | B3: BRANCO 56G/M² | C3: 7-14-21 | D3: 50 | E3: 6049.64
A4: BRN075 | B4: BRANCO 70g | D4: 75 | E4: 5497.94
A5: BRN075 | B5: BRANCO 75g | D5: 75 | E5: 5497.94
A6: BRN100 | C6: 7-14-21 | D6: 100 | E6: 0
A7: BRN110 | B7: Branco 110 | C7: 7-14-21 | D7: 110 | E7: 0
A8: BRN120 | B8: BRANCO WTL | C8: 7-14-21 | D8: 120 | E8: 6215.19
A9: BRN130 | B9: BRANCO WTL | C9: 7-14-21 | D9: 120 | E9: 5882.97
A10: BRN140 | B10: BRANCO WTL | C10: 7-14-21 | D10: 140 | E10: 5882.97
A11: BRN150 | B11: BRANCO WTL | C11: 7-14-21 | D11: 150 | E11: 5882.97
A12: BRN175 | B12: BRANCO WTL KLABIN | C12: 7-14-21 | D12: 175 | E12: 6644.74
A13: BRN180 | B13: BRANCO | C13: 7-14-21 | D13: 175 | E13: =E12 -> 6644.74
A14: BRN63 | B14: BRANCO | C14: 7-14-21 | D14: 50 | E14: =E3 -> 6049.64
A15: BRN90 | B15: BRANCO 90G/M² | C15: 20-40-60 | D15: 90 | E15: 5980
A16: CNP190 | B16: COUTING NEOPACK | C16: 20-40-60 | D16: 190 | E16: 7756.23
A17: KKN 150 | B17: KRAFT 150g | D17: 150 | E17: 5095.6
A18: KKN 375 | B18: PAPEL KRAFT 375G | C18: 7-14-21 | D18: 375 | E18: 5095.6
A19: KKN080 | B19: KRAFT P/ ACOPLAGEM | C19: 7-14-21 | D19: 80 | E19: 6119.67
A20: KKN90 | B20: KRAFT | C20: 7-14-21 | D20: 100 | E20: 5095.6
A21: KKN100 | B21: KRAFT | C21: 7-14-21 | D21: 100 | E21: 5095.6
A22: KKN110 | B22: KRAFT | C22: 7-14-21 | D22: 115 | E22: 5095.6
A23: KKN125 | B23: KRAFT | C23: 7-14-21 | D23: 125 | E23: 5095.6
A24: KKN130 | B24: KRAFT | C24: 7-14-21 | D24: 125 | E24: 5095.6
A25: KKN140 | B25: KRAFT | C25: 7-14-21 | D25: 140 | E25: 5095.6
A26: KKN155 | B26: KRAFT 155 | D26: 155 | E26: 5095.6
A27: KKN160 | B27: KRAFT NORMAL 160g | C27: 7-14-21 | D27: 170 | E27: 5095.6
A28: KKN170 | B28: KRAFT NORMAL 170G | C28: 7-14-21 | D28: 180 | E28: 5095.6
A29: KKN175 | B29: KRAFT | C29: 7-14-21 | D29: 185 | E29: 5095.6
A30: KKN185 | B30: KRAFT | C30: 7-14-21 | D30: 185 | E30: 5095.6
A31: KKN190 | B31: KRAFT | C31: 7-14-21 | D31: 200 | E31: 5095.6
A32: KKN200 | B32: KRAFT | C32: 7-14-21 | D32: 200 | E32: 5095.6
A33: KKN240 | B33: KRAFT | C33: 7-14-21 | D33: 240 | E33: 5095.6
A34: KKN280 | B34: KRAFT 280 | C34: 7-14-21 | D34: 280 | E34: 5095.6
A35: KKP110 | B35: KRAFT 110g PLASTIFICADO (15g) | C35: 7-14-21 | D35: 130 | E35: =E22+4640 -> 9735.6
A36: KKP125 | B36: KKN125(125g) + Plastif(15g) | C36: 7-14-21 | D36: 145 | E36: =E35 -> 9735.6
A37: MEN 190 | B37: MIOLO ESPECIAL 190 | C37: 7-14-21 | D37: 190 | E37: 2994.47
A38: MEN 350 | B38: MIOLO 350 GRAMAS ESPECIAL | C38: 7-14-21 | D38: 350 | E38: 2994.47
A39: MEN150 | B39: MIOLO RECICLADO | C39: 7-14-21 | D39: 150 | E39: 2994.47
A40: MEN165 | B40: MIOLO RECICLADO | C40: 7-14-21 | D40: 165 | E40: 2994.47
...

Sheet Agosto-2022
A1: Papel | B1: Descrição | C1: Grupo | D1: Gramatura (g/m²) | E1: Custo ($/t)|Valor REAL
A2: 0 | B2: OUTROS | C2: 20-40-60 | D2: 1 | E2: 1
A3: BRN 056 | B3: BRANCO 56G/M² | C3: 7-14-21 | D3: 50 | E3: 7093.63
A4: BRN075 | B4: BRANCO 70g | D4: 75 | E4: 5497.94
A5: BRN075 | B5: BRANCO 75g | D5: 75 | E5: 5497.94
A6: BRN100 | C6: 7-14-21 | D6: 100 | E6: 0
A7: BRN110 | B7: Branco 110 | C7: 7-14-21 | D7: 110 | E7: 0
A8: BRN120 | B8: BRANCO WTL | C8: 7-14-21 | D8: 120 | E8: 5280.81
A9: BRN130 | B9: BRANCO WTL | C9: 7-14-21 | D9: 120 | E9: 5280.81
A10: BRN140 | B10: BRANCO WTL | C10: 7-14-21 | D10: 140 | E10: 5280.81
A11: BRN150 | B11: BRANCO WTL | C11: 7-14-21 | D11: 150 | E11: 5280.81
A12: BRN175 | B12: BRANCO WTL KLABIN | C12: 7-14-21 | D12: 175 | E12: 6644.74
A13: BRN180 | B13: BRANCO | C13: 7-14-21 | D13: 175 | E13: =E12 -> 6644.74
A14: BRN63 | B14: BRANCO | C14: 7-14-21 | D14: 50 | E14: =E3 -> 7093.63
A15: BRN90 | B15: BRANCO 90G/M² | C15: 20-40-60 | D15: 90 | E15: 7517.91
A16: CNP190 | B16: COUTING NEOPACK | C16: 20-40-60 | D16: 190 | E16: 7730.43
A17: KKN 150 | B17: KRAFT 150g | D17: 150 | E17: 4968.79
A18: KKN 375 | B18: PAPEL KRAFT 375G | C18: 7-14-21 | D18: 375 | E18: 4968.79
A19: KKN080 | B19: KRAFT P/ ACOPLAGEM | C19: 7-14-21 | D19: 80 | E19: 6169.67
A20: KKN90 | B20: KRAFT | C20: 7-14-21 | D20: 100 | E20: 4968.79
A21: KKN100 | B21: KRAFT | C21: 7-14-21 | D21: 100 | E21: 4968.79
A22: KKN110 | B22: KRAFT | C22: 7-14-21 | D22: 115 | E22: 4968.79
A23: KKN125 | B23: KRAFT | C23: 7-14-21 | D23: 125 | E23: 4968.79
A24: KKN130 | B24: KRAFT | C24: 7-14-21 | D24: 125 | E24: 4968.79
A25: KKN140 | B25: KRAFT | C25: 7-14-21 | D25: 140 | E25: 4968.79
A26: KKN155 | B26: KRAFT 155 | D26: 155 | E26: 4968.79
A27: KKN160 | B27: KRAFT NORMAL 160g | C27: 7-14-21 | D27: 170 | E27: 4968.79
A28: KKN170 | B28: KRAFT NORMAL 170G | C28: 7-14-21 | D28: 180 | E28: 4968.79
A29: KKN175 | B29: KRAFT | C29: 7-14-21 | D29: 185 | E29: 4968.79
A30: KKN185 | B30: KRAFT | C30: 7-14-21 | D30: 185 | E30: 4968.79
A31: KKN190 | B31: KRAFT | C31: 7-14-21 | D31: 200 | E31: 4968.79
A32: KKN200 | B32: KRAFT | C32: 7-14-21 | D32: 200 | E32: 4968.79
A33: KKN240 | B33: KRAFT | C33: 7-14-21 | D33: 240 | E33: 4968.79
A34: KKN280 | B34: KRAFT 280 | C34: 7-14-21 | D34: 280 | E34: 4968.79
A35: KKP110 | B35: KRAFT 110g PLASTIFICADO (15g) | C35: 7-14-21 | D35: 130 | E35: =E22+4640 -> 9608.79
A36: KKP125 | B36: KKN125(125g) + Plastif(15g) | C36: 7-14-21 | D36: 145 | E36: =E35 -> 9608.79
A37: MEN 190 | B37: MIOLO ESPECIAL 190 | C37: 7-14-21 | D37: 190 | E37: 3310.25
A38: MEN 350 | B38: MIOLO 350 GRAMAS ESPECIAL | C38: 7-14-21 | D38: 350 | E38: 3310.25
A39: MEN150 | B39: MIOLO RECICLADO | C39: 7-14-21 | D39: 150 | E39: 3310.25
A40: MEN165 | B40: MIOLO RECICLADO | C40: 7-14-21 | D40: 165 | E40: 3310.25
...

Sheet Setembro-2022
A1: Papel | B1: Descrição | C1: Grupo | D1: Gramatura (g/m²) | E1: Custo ($/t)|Valor REAL
A2: 0 | B2: OUTROS | C2: 20-40-60 | D2: 1 | E2: 1
A3: BRN 056 | B3: BRANCO 56G/M² | C3: 7-14-21 | D3: 50 | E3: 5486.54
A4: BRN075 | B4: BRANCO 70g | D4: 75 | E4: 5497.94
A5: BRN075 | B5: BRANCO 75g | D5: 75 | E5: 5497.94
A6: BRN100 | C6: 7-14-21 | D6: 100 | E6: 0
A7: BRN110 | B7: Branco 110 | C7: 7-14-21 | D7: 110 | E7: 0
A8: BRN120 | B8: BRANCO WTL | C8: 7-14-21 | D8: 120 | E8: 5482.58
A9: BRN130 | B9: BRANCO WTL | C9: 7-14-21 | D9: 120 | E9: 5482.58
A10: BRN140 | B10: BRANCO WTL | C10: 7-14-21 | D10: 140 | E10: 5482.58
A11: BRN150 | B11: BRANCO WTL | C11: 7-14-21 | D11: 150 | E11: 5100.51
A12: BRN175 | B12: BRANCO WTL KLABIN | C12: 7-14-21 | D12: 175 | E12: 6644.74
A13: BRN180 | B13: BRANCO | C13: 7-14-21 | D13: 175 | E13: =E12 -> 6644.74
A14: BRN63 | B14: BRANCO | C14: 7-14-21 | D14: 50 | E14: =E3 -> 5486.54
A15: BRN90 | B15: BRANCO 90G/M² | C15: 20-40-60 | D15: 90 | E15: 4855.15
A16: CNP190 | B16: COUTING NEOPACK | C16: 20-40-60 | D16: 190 | E16: 8274.64
A17: KKN 150 | B17: KRAFT 150g | D17: 150 | E17: 5125.19
A18: KKN 375 | B18: PAPEL KRAFT 375G | C18: 7-14-21 | D18: 375 | E18: 5125.19
A19: KKN080 | B19: KRAFT P/ ACOPLAGEM | C19: 7-14-21 | D19: 80 | E19: 6170.15
A20: KKN90 | B20: KRAFT | C20: 7-14-21 | D20: 100 | E20: 5125.19
A21: KKN100 | B21: KRAFT | C21: 7-14-21 | D21: 100 | E21: 5125.19
A22: KKN110 | B22: KRAFT | C22: 7-14-21 | D22: 115 | E22: 5125.19
A23: KKN125 | B23: KRAFT | C23: 7-14-21 | D23: 125 | E23: 5125.19
A24: KKN130 | B24: KRAFT | C24: 7-14-21 | D24: 125 | E24: 5125.19
A25: KKN140 | B25: KRAFT | C25: 7-14-21 | D25: 140 | E25: 5125.19
A26: KKN155 | B26: KRAFT 155 | D26: 155 | E26: 5125.19
A27: KKN160 | B27: KRAFT NORMAL 160g | C27: 7-14-21 | D27: 170 | E27: 5125.19
A28: KKN170 | B28: KRAFT NORMAL 170G | C28: 7-14-21 | D28: 180 | E28: 5125.19
A29: KKN175 | B29: KRAFT | C29: 7-14-21 | D29: 185 | E29: 5125.19
A30: KKN185 | B30: KRAFT | C30: 7-14-21 | D30: 185 | E30: 5125.19
A31: KKN190 | B31: KRAFT | C31: 7-14-21 | D31: 200 | E31: 5125.19
A32: KKN200 | B32: KRAFT | C32: 7-14-21 | D32: 200 | E32: 5125.19
A33: KKN240 | B33: KRAFT | C33: 7-14-21 | D33: 240 | E33: 5125.19
A34: KKN280 | B34: KRAFT 280 | C34: 7-14-21 | D34: 280 | E34: 5125.19
A35: KKP110 | B35: KRAFT 110g PLASTIFICADO (15g) | C35: 7-14-21 | D35: 130 | E35: =E22+4640 -> 9765.19
A36: KKP125 | B36: KKN125(125g) + Plastif(15g) | C36: 7-14-21 | D36: 145 | E36: =E35 -> 9765.19
A37: MEN 190 | B37: MIOLO ESPECIAL 190 | C37: 7-14-21 | D37: 190 | E37: 3290.05
A38: MEN 350 | B38: MIOLO 350 GRAMAS ESPECIAL | C38: 7-14-21 | D38: 350 | E38: 3290.05
A39: MEN150 | B39: MIOLO RECICLADO | C39: 7-14-21 | D39: 150 | E39: 3290.05
A40: MEN165 | B40: MIOLO RECICLADO | C40: 7-14-21 | D40: 165 | E40: 3290.05
...

Sheet Outubro-2022
A1: Papel | B1: Descrição | C1: Grupo | D1: Gramatura (g/m²) | E1: Custo ($/t)|Valor REAL
A2: 0 | B2: OUTROS | C2: 20-40-60 | D2: 1 | E2: 1
A3: BRN 056 | B3: BRANCO 56G/M² | C3: 7-14-21 | D3: 50 | E3: 7585.93 | G3: =E3/5486.54 -> 1.3826437 | H3: de diferença em relação ao mês anterior
A4: BRN075 | B4: BRANCO 70g | D4: 75 | E4: =E3 -> 7585.93
A5: BRN075 | B5: BRANCO 75g | D5: 75 | E5: =E3 -> 7585.93
A6: BRN100 | C6: 7-14-21 | D6: 100 | E6: 0
A7: BRN110 | B7: Branco 110 | C7: 7-14-21 | D7: 110 | E7: 0
A8: BRN120 | B8: BRANCO WTL | C8: 7-14-21 | D8: 120 | E8: 5902.73
A9: BRN130 | B9: BRANCO WTL | C9: 7-14-21 | D9: 120 | E9: =E8 -> 5902.73
A10: BRN140 | B10: BRANCO WTL | C10: 7-14-21 | D10: 140 | E10: =E8 -> 5902.73
A11: BRN150 | B11: BRANCO WTL | C11: 7-14-21 | D11: 150 | E11: 5100.51
A12: BRN175 | B12: BRANCO WTL KLABIN | C12: 7-14-21 | D12: 175 | E12: 6644.74
A13: BRN180 | B13: BRANCO | C13: 7-14-21 | D13: 175 | E13: =E12 -> 6644.74
A14: BRN63 | B14: BRANCO | C14: 7-14-21 | D14: 50 | E14: =E3 -> 7585.93
A15: BRN90 | B15: BRANCO 90G/M² | C15: 20-40-60 | D15: 90 | E15: 6413.91 | G15: =E15/4855.15 -> 1.3210529 | H15: de diferença em relação ao mês anterior
A16: CNP190 | B16: COUTING NEOPACK | C16: 20-40-60 | D16: 190 | E16: 7856.01
A17: KKN 150 | B17: KRAFT 150g | D17: 150 | E17: 5014.28
A18: KKN 375 | B18: PAPEL KRAFT 375G | C18: 7-14-21 | D18: 375 | E18: 5014.28
A19: KKN080 | B19: KRAFT P/ ACOPLAGEM | C19: 7-14-21 | D19: 80 | E19: 6056.63
A20: KKN90 | B20: KRAFT | C20: 7-14-21 | D20: 100 | E20: 5014.28
A21: KKN100 | B21: KRAFT | C21: 7-14-21 | D21: 100 | E21: 5014.28
A22: KKN110 | B22: KRAFT | C22: 7-14-21 | D22: 115 | E22: 5014.28
A23: KKN125 | B23: KRAFT | C23: 7-14-21 | D23: 125 | E23: 5014.28
A24: KKN130 | B24: KRAFT | C24: 7-14-21 | D24: 125 | E24: 5014.28
A25: KKN140 | B25: KRAFT | C25: 7-14-21 | D25: 140 | E25: 5014.28
A26: KKN155 | B26: KRAFT 155 | D26: 155 | E26: 5014.28
A27: KKN160 | B27: KRAFT NORMAL 160g | C27: 7-14-21 | D27: 170 | E27: 5014.28
A28: KKN170 | B28: KRAFT NORMAL 170G | C28: 7-14-21 | D28: 180 | E28: 5014.28
A29: KKN175 | B29: KRAFT | C29: 7-14-21 | D29: 185 | E29: 5014.28
A30: KKN185 | B30: KRAFT | C30: 7-14-21 | D30: 185 | E30: 5014.28
A31: KKN190 | B31: KRAFT | C31: 7-14-21 | D31: 200 | E31: 5014.28
A32: KKN200 | B32: KRAFT | C32: 7-14-21 | D32: 200 | E32: 5014.28
A33: KKN240 | B33: KRAFT | C33: 7-14-21 | D33: 240 | E33: 5014.28
A34: KKN280 | B34: KRAFT 280 | C34: 7-14-21 | D34: 280 | E34: 5014.28
A35: KKP110 | B35: KRAFT 110g PLASTIFICADO (15g) | C35: 7-14-21 | D35: 130 | E35: =E36 -> 6703.03
A36: KKP125 | B36: KKN125(125g) + Plastif(15g) | C36: 7-14-21 | D36: 145 | E36: 6703.03
A37: MEN 190 | B37: MIOLO ESPECIAL 190 | C37: 7-14-21 | D37: 190 | E37: 3390.07
A38: MEN 350 | B38: MIOLO 350 GRAMAS ESPECIAL | C38: 7-14-21 | D38: 350 | E38: 3390.07
A39: MEN150 | B39: MIOLO RECICLADO | C39: 7-14-21 | D39: 150 | E39: 3390.07
A40: MEN165 | B40: MIOLO RECICLADO | C40: 7-14-21 | D40: 165 | E40: 3390.07
...

Sheet Novembro-2022
A1: Papel | B1: Descrição | C1: Grupo | D1: Gramatura (g/m²) | E1: Custo ($/t)|Valor REAL
A2: 0 | B2: OUTROS | C2: 20-40-60 | D2: 1 | E2: 1
A3: BRN 056 | B3: BRANCO 56G/M² | C3: 7-14-21 | D3: 50 | E3: 7585.93
A4: BRN075 | B4: BRANCO 70g | D4: 75 | E4: =E3 -> 7585.93
A5: BRN075 | B5: BRANCO 75g | D5: 75 | E5: =E3 -> 7585.93
A6: BRN100 | C6: 7-14-21 | D6: 100 | E6: 0
A7: BRN110 | B7: Branco 110 | C7: 7-14-21 | D7: 110 | E7: 0
A8: BRN120 | B8: BRANCO WTL | C8: 7-14-21 | D8: 120 | E8: 5280.81
A9: BRN130 | B9: BRANCO WTL | C9: 7-14-21 | D9: 120 | E9: =E8 -> 5280.81
A10: BRN140 | B10: BRANCO WTL | C10: 7-14-21 | D10: 140 | E10: =E8 -> 5280.81
A11: BRN150 | B11: BRANCO WTL | C11: 7-14-21 | D11: 150 | E11: 5882.97
A12: BRN175 | B12: BRANCO WTL KLABIN | C12: 7-14-21 | D12: 175 | E12: 6644.74
A13: BRN180 | B13: BRANCO | C13: 7-14-21 | D13: 175 | E13: =E12 -> 6644.74
A14: BRN63 | B14: BRANCO | C14: 7-14-21 | D14: 50 | E14: =E3 -> 7585.93
A15: BRN90 | B15: BRANCO 90G/M² | C15: 20-40-60 | D15: 90 | E15: 6724.38
A16: CNP190 | B16: COUTING NEOPACK | C16: 20-40-60 | D16: 190 | E16: 7856.01
A17: KKN 150 | B17: KRAFT 150g | D17: 150 | E17: 5385.42
A18: KKN 375 | B18: PAPEL KRAFT 375G | C18: 7-14-21 | D18: 375 | E18: 5385.42
A19: KKN080 | B19: KRAFT P/ ACOPLAGEM | C19: 7-14-21 | D19: 80 | E19: 6056.63
A20: KKN90 | B20: KRAFT | C20: 7-14-21 | D20: 100 | E20: 5385.42
A21: KKN100 | B21: KRAFT | C21: 7-14-21 | D21: 100 | E21: 5385.42
A22: KKN110 | B22: KRAFT | C22: 7-14-21 | D22: 115 | E22: 5385.42
A23: KKN125 | B23: KRAFT | C23: 7-14-21 | D23: 125 | E23: 5385.42
A24: KKN130 | B24: KRAFT | C24: 7-14-21 | D24: 125 | E24: 5385.42
A25: KKN140 | B25: KRAFT | C25: 7-14-21 | D25: 140 | E25: 5385.42
A26: KKN155 | B26: KRAFT 155 | D26: 155 | E26: 5385.42
A27: KKN160 | B27: KRAFT NORMAL 160g | C27: 7-14-21 | D27: 170 | E27: 5385.42
A28: KKN170 | B28: KRAFT NORMAL 170G | C28: 7-14-21 | D28: 180 | E28: 5385.42
A29: KKN175 | B29: KRAFT | C29: 7-14-21 | D29: 185 | E29: 5385.42
A30: KKN185 | B30: KRAFT | C30: 7-14-21 | D30: 185 | E30: 5385.42
A31: KKN190 | B31: KRAFT | C31: 7-14-21 | D31: 200 | E31: 5385.42
A32: KKN200 | B32: KRAFT | C32: 7-14-21 | D32: 200 | E32: 5385.42
A33: KKN240 | B33: KRAFT | C33: 7-14-21 | D33: 240 | E33: 5385.42
A34: KKN280 | B34: KRAFT 280 | C34: 7-14-21 | D34: 280 | E34: 5385.42
A35: KKP110 | B35: KRAFT 110g PLASTIFICADO (15g) | C35: 7-14-21 | D35: 130 | E35: =E36 -> 6703.03
A36: KKP125 | B36: KKN125(125g) + Plastif(15g) | C36: 7-14-21 | D36: 145 | E36: 6703.03
A37: MEN 190 | B37: MIOLO ESPECIAL 190 | C37: 7-14-21 | D37: 190 | E37: 3337.28
A38: MEN 350 | B38: MIOLO 350 GRAMAS ESPECIAL | C38: 7-14-21 | D38: 350 | E38: 3337.28
A39: MEN150 | B39: MIOLO RECICLADO | C39: 7-14-21 | D39: 150 | E39: 3337.28
A40: MEN165 | B40: MIOLO RECICLADO | C40: 7-14-21 | D40: 165 | E40: 3337.28
...

Sheet Dezembro-2022
A1: Papel | B1: Descrição | C1: Grupo | D1: Gramatura (g/m²) | E1: Custo ($/t)|Valor REAL
A2: 0 | B2: OUTROS | C2: 20-40-60 | D2: 1 | E2: 1
A3: BRN 056 | B3: BRANCO 56G/M² | C3: 7-14-21 | D3: 50 | E3: 7585.93
A4: BRN075 | B4: BRANCO 70g | D4: 75 | E4: =E3 -> 7585.93
A5: BRN075 | B5: BRANCO 75g | D5: 75 | E5: =E3 -> 7585.93
A6: BRN100 | C6: 7-14-21 | D6: 100 | E6: 0
A7: BRN110 | B7: Branco 110 | C7: 7-14-21 | D7: 110 | E7: 0
A8: BRN120 | B8: BRANCO WTL | C8: 7-14-21 | D8: 120 | E8: 5650
A9: BRN130 | B9: BRANCO WTL | C9: 7-14-21 | D9: 120 | E9: 5902.73
A10: BRN140 | B10: BRANCO WTL | C10: 7-14-21 | D10: 140 | E10: 5902.73
A11: BRN150 | B11: BRANCO WTL | C11: 7-14-21 | D11: 150 | E11: 6590
A12: BRN175 | B12: BRANCO WTL KLABIN | C12: 7-14-21 | D12: 175 | E12: 6590 | G12: Variação de - 0,87%
A13: BRN180 | B13: BRANCO | C13: 7-14-21 | D13: 175 | E13: 6644.74
A14: BRN63 | B14: BRANCO | C14: 7-14-21 | D14: 50 | E14: =E3 -> 7585.93
A15: BRN90 | B15: BRANCO 90G/M² | C15: 20-40-60 | D15: 90 | E15: 5650.4 | G15: Variação de - 15,97%
A16: CNP190 | B16: COUTING NEOPACK | C16: 20-40-60 | D16: 190 | E16: 7856.01
A17: KKN 150 | B17: KRAFT 150g | D17: 150 | E17: 5289.26 | G17: Variação de - 1,79%
A18: KKN 375 | B18: PAPEL KRAFT 375G | C18: 7-14-21 | D18: 375 | E18: 7400
A19: KKN080 | B19: KRAFT P/ ACOPLAGEM | C19: 7-14-21 | D19: 80 | E19: 6056.63
A20: KKN90 | B20: KRAFT | C20: 7-14-21 | D20: 100 | E20: 5289.26
A21: KKN100 | B21: KRAFT | C21: 7-14-21 | D21: 100 | E21: 5289.26
A22: KKN110 | B22: KRAFT | C22: 7-14-21 | D22: 115 | E22: 5289.26
A23: KKN125 | B23: KRAFT | C23: 7-14-21 | D23: 125 | E23: 5289.26
A24: KKN130 | B24: KRAFT | C24: 7-14-21 | D24: 125 | E24: 5289.26
A25: KKN140 | B25: KRAFT | C25: 7-14-21 | D25: 140 | E25: 5289.26
A26: KKN155 | B26: KRAFT 155 | D26: 155 | E26: 5289.26
A27: KKN160 | B27: KRAFT NORMAL 160g | C27: 7-14-21 | D27: 170 | E27: 5289.26
A28: KKN170 | B28: KRAFT NORMAL 170G | C28: 7-14-21 | D28: 180 | E28: 5289.26
A29: KKN175 | B29: KRAFT | C29: 7-14-21 | D29: 185 | E29: 5289.26
A30: KKN185 | B30: KRAFT | C30: 7-14-21 | D30: 185 | E30: 5289.26
A31: KKN190 | B31: KRAFT | C31: 7-14-21 | D31: 200 | E31: 5289.26
A32: KKN200 | B32: KRAFT | C32: 7-14-21 | D32: 200 | E32: 5289.26
A33: KKN240 | B33: KRAFT | C33: 7-14-21 | D33: 240 | E33: 5289.26
A34: KKN280 | B34: KRAFT 280 | C34: 7-14-21 | D34: 280 | E34: 7370
A35: KKP110 | B35: KRAFT 110g PLASTIFICADO (15g) | C35: 7-14-21 | D35: 130 | E35: =E36 -> 6703.03
A36: KKP125 | B36: KKN125(125g) + Plastif(15g) | C36: 7-14-21 | D36: 145 | E36: 6703.03
A37: MEN 190 | B37: MIOLO ESPECIAL 190 | C37: 7-14-21 | D37: 190 | E37: 3356.52 | G37: Variação de 0,58%
A38: MEN 350 | B38: MIOLO 350 GRAMAS ESPECIAL | C38: 7-14-21 | D38: 350 | E38: 3356.52
A39: MEN150 | B39: MIOLO RECICLADO | C39: 7-14-21 | D39: 150 | E39: 3356.52
A40: MEN165 | B40: MIOLO RECICLADO | C40: 7-14-21 | D40: 165 | E40: 3356.52
...

Sheet Janeiro-2023
A1: Papel | B1: Descrição | C1: Grupo | D1: Gramatura (g/m²) | E1: Custo ($/t)|Valor REAL
A2: 0 | B2: OUTROS | C2: 20-40-60 | D2: 1 | E2: 1
A3: BRN 056 | B3: BRANCO 56G/M² | C3: 7-14-21 | D3: 50 | E3: 6694.71
A4: BRN075 | B4: BRANCO 70g | D4: 75 | E4: =E3 -> 6694.71
A5: BRN075 | B5: BRANCO 75g | D5: 75 | E5: =E3 -> 6694.71
A6: BRN100 | C6: 7-14-21 | D6: 100 | E6: 0
A7: BRN110 | B7: Branco 110 | C7: 7-14-21 | D7: 110 | E7: 0
A8: BRN120 | B8: BRANCO WTL | C8: 7-14-21 | D8: 120 | E8: =6.356*1000 -> 6356
A9: BRN130 | B9: BRANCO WTL | C9: 7-14-21 | D9: 120 | E9: 5902.73
A10: BRN140 | B10: BRANCO WTL | C10: 7-14-21 | D10: 140 | E10: 5902.73
A11: BRN150 | B11: BRANCO WTL | C11: 7-14-21 | D11: 150 | E11: 5458
A12: BRN175 | B12: BRANCO WTL KLABIN | C12: 7-14-21 | D12: 175 | E12: =6.296*1000 -> 6296 | G12: Variação de - 0,87%
A13: BRN180 | B13: BRANCO | C13: 7-14-21 | D13: 175 | E13: 6644.74
A14: BRN63 | B14: BRANCO | C14: 7-14-21 | D14: 50 | E14: =E3 -> 6694.71
A15: BRN90 | B15: BRANCO 90G/M² | C15: 20-40-60 | D15: 90 | E15: 5650.4 | G15: Variação de - 15,97%
A16: CNP190 | B16: COUTING NEOPACK | C16: 20-40-60 | D16: 190 | E16: 7856.01
A17: KKN 150 | B17: KRAFT 150g | D17: 150 | E17: 5289.26 | G17: Variação de - 1,79%
A18: KKN 375 | B18: PAPEL KRAFT 375G | C18: 7-14-21 | D18: 375 | E18: 5708
A19: KKN080 | B19: KRAFT P/ ACOPLAGEM | C19: 7-14-21 | D19: 80 | E19: 6284
A20: KKN90 | B20: KRAFT | C20: 7-14-21 | D20: 100 | E20: 5289.26
A21: KKN100 | B21: KRAFT | C21: 7-14-21 | D21: 100 | E21: 5289.26
A22: KKN110 | B22: KRAFT | C22: 7-14-21 | D22: 115 | E22: 4896
A23: KKN125 | B23: KRAFT | C23: 7-14-21 | D23: 125 | E23: =5.136*1000 -> 5136
A24: KKN130 | B24: KRAFT | C24: 7-14-21 | D24: 125 | E24: 5289.26
A25: KKN140 | B25: KRAFT | C25: 7-14-21 | D25: 140 | E25: 5289.26
A26: KKN155 | B26: KRAFT 155 | D26: 155 | E26: 5289.26
A27: KKN160 | B27: KRAFT NORMAL 160g | C27: 7-14-21 | D27: 170 | E27: 5289.26
A28: KKN170 | B28: KRAFT NORMAL 170G | C28: 7-14-21 | D28: 180 | E28: 5289.26
A29: KKN175 | B29: KRAFT | C29: 7-14-21 | D29: 185 | E29: 5289.26
A30: KKN185 | B30: KRAFT | C30: 7-14-21 | D30: 185 | E30: =5.213*1000 -> 5213
A31: KKN190 | B31: KRAFT | C31: 7-14-21 | D31: 200 | E31: 5289.26
A32: KKN200 | B32: KRAFT | C32: 7-14-21 | D32: 200 | E32: 5289.26
A33: KKN240 | B33: KRAFT | C33: 7-14-21 | D33: 240 | E33: 5289.26
A34: KKN280 | B34: KRAFT 280 | C34: 7-14-21 | D34: 280 | E34: 7370
A35: KKP110 | B35: KRAFT 110g PLASTIFICADO (15g) | C35: 7-14-21 | D35: 130 | E35: =E36 -> 6703.03
A36: KKP125 | B36: KKN125(125g) + Plastif(15g) | C36: 7-14-21 | D36: 145 | E36: 6703.03
A37: MEN 190 | B37: MIOLO ESPECIAL 190 | C37: 7-14-21 | D37: 190 | E37: 3487 | G37: Variação de 0,58%
A38: MEN 350 | B38: MIOLO 350 GRAMAS ESPECIAL | C38: 7-14-21 | D38: 350 | E38: 3356.52
A39: MEN150 | B39: MIOLO RECICLADO | C39: 7-14-21 | D39: 150 | E39: 3448
A40: MEN165 | B40: MIOLO RECICLADO | C40: 7-14-21 | D40: 165 | E40: 3356.52
...

Sheet Fevereiro-2023
A1: Papel | B1: Descrição | C1: Grupo | D1: Gramatura (g/m²) | E1: Custo ($/t)|Valor REAL
A2: 0 | B2: OUTROS | C2: 20-40-60 | D2: 1 | E2: 1
A3: BRN 056 | B3: BRANCO 56G/M² | C3: 7-14-21 | D3: 50 | E3: 6694.71
A4: BRN075 | B4: BRANCO 70g | D4: 75 | E4: =E3 -> 6694.71
A5: BRN075 | B5: BRANCO 75g | D5: 75 | E5: =E3 -> 6694.71
A6: BRN100 | C6: 7-14-21 | D6: 100 | E6: 0
A7: BRN110 | B7: Branco 110 | C7: 7-14-21 | D7: 110 | E7: 0
A8: BRN120 | B8: BRANCO WTL | C8: 7-14-21 | D8: 120 | E8: 7568
A9: BRN130 | B9: BRANCO WTL | C9: 7-14-21 | D9: 120 | E9: 5902.73
A10: BRN140 | B10: BRANCO WTL | C10: 7-14-21 | D10: 140 | E10: 5394
A11: BRN150 | B11: BRANCO WTL | C11: 7-14-21 | D11: 150 | E11: 5394
A12: BRN175 | B12: BRANCO WTL KLABIN | C12: 7-14-21 | D12: 175 | E12: =6.296*1000 -> 6296 | G12: Variação de - 0,87%
A13: BRN180 | B13: BRANCO | C13: 7-14-21 | D13: 175 | E13: 6644.74
A14: BRN63 | B14: BRANCO | C14: 7-14-21 | D14: 50 | E14: 7154
A15: BRN90 | B15: BRANCO 90G/M² | C15: 20-40-60 | D15: 90 | E15: 5984 | G15: Variação de - 15,97%
A16: CNP190 | B16: COUTING NEOPACK | C16: 20-40-60 | D16: 190 | E16: 7856.01
A17: KKN 150 | B17: KRAFT 150g | D17: 150 | E17: 5289.26 | G17: Variação de - 1,79%
A18: KKN 375 | B18: PAPEL KRAFT 375G | C18: 7-14-21 | D18: 375 | E18: 5708
A19: KKN080 | B19: KRAFT P/ ACOPLAGEM | C19: 7-14-21 | D19: 80 | E19: 7089
A20: KKN90 | B20: KRAFT | C20: 7-14-21 | D20: 100 | E20: 5289.26
A21: KKN100 | B21: KRAFT | C21: 7-14-21 | D21: 100 | E21: 5289.26
A22: KKN110 | B22: KRAFT | C22: 7-14-21 | D22: 115 | E22: 4896
A23: KKN125 | B23: KRAFT | C23: 7-14-21 | D23: 125 | E23: 5210
A24: KKN130 | B24: KRAFT | C24: 7-14-21 | D24: 125 | E24: 5289.26
A25: KKN140 | B25: KRAFT | C25: 7-14-21 | D25: 140 | E25: 5289.26
A26: KKN155 | B26: KRAFT 155 | D26: 155 | E26: 5289.26
A27: KKN160 | B27: KRAFT NORMAL 160g | C27: 7-14-21 | D27: 170 | E27: 5289.26
A28: KKN170 | B28: KRAFT NORMAL 170G | C28: 7-14-21 | D28: 180 | E28: 5289.26
A29: KKN175 | B29: KRAFT | C29: 7-14-21 | D29: 185 | E29: 5244
A30: KKN185 | B30: KRAFT | C30: 7-14-21 | D30: 185 | E30: 5244
A31: KKN190 | B31: KRAFT | C31: 7-14-21 | D31: 200 | E31: 5289.26
A32: KKN200 | B32: KRAFT | C32: 7-14-21 | D32: 200 | E32: 5289.26
A33: KKN240 | B33: KRAFT | C33: 7-14-21 | D33: 240 | E33: 5289.26
A34: KKN280 | B34: KRAFT 280 | C34: 7-14-21 | D34: 280 | E34: 7370
A35: KKP110 | B35: KRAFT 110g PLASTIFICADO (15g) | C35: 7-14-21 | D35: 130 | E35: =E36 -> 9170
A36: KKP125 | B36: KKN125(125g) + Plastif(15g) | C36: 7-14-21 | D36: 145 | E36: 9170
A37: MEN 190 | B37: MIOLO ESPECIAL 190 | C37: 7-14-21 | D37: 190 | E37: 3283 | G37: Variação de 0,58%
A38: MEN 350 | B38: MIOLO 350 GRAMAS ESPECIAL | C38: 7-14-21 | D38: 350 | E38: 3356.52
A39: MEN150 | B39: MIOLO RECICLADO | C39: 7-14-21 | D39: 150 | E39: 3382
A40: MEN165 | B40: MIOLO RECICLADO | C40: 7-14-21 | D40: 165 | E40: 3356.52
...

Sheet Março-2023
A1: Papel | B1: Descrição | C1: Grupo | D1: Gramatura (g/m²) | E1: Custo ($/t)|Valor REAL
A2: 0 | B2: OUTROS | C2: 20-40-60 | D2: 1 | E2: 1
A3: BRN 056 | B3: BRANCO 56G/M² | C3: 7-14-21 | D3: 50 | E3: 6694.71
A4: BRN075 | B4: BRANCO 70g | D4: 75 | E4: =E3 -> 6694.71
A5: BRN075 | B5: BRANCO 75g | D5: 75 | E5: =E3 -> 6694.71
A6: BRN100 | C6: 7-14-21 | D6: 100 | E6: 0
A7: BRN110 | B7: Branco 110 | C7: 7-14-21 | D7: 110 | E7: 0
A8: BRN120 | B8: BRANCO WTL | C8: 7-14-21 | D8: 120 | E8: 5943
A9: BRN130 | B9: BRANCO WTL | C9: 7-14-21 | D9: 120 | E9: 5902.73
A10: BRN140 | B10: BRANCO WTL | C10: 7-14-21 | D10: 140 | E10: 5394
A11: BRN150 | B11: BRANCO WTL | C11: 7-14-21 | D11: 150 | E11: 5440
A12: BRN175 | B12: BRANCO WTL KLABIN | C12: 7-14-21 | D12: 175 | E12: =6.296*1000 -> 6296 | G12: Variação de - 0,87%
A13: BRN180 | B13: BRANCO | C13: 7-14-21 | D13: 175 | E13: 6644.74
A14: BRN63 | B14: BRANCO | C14: 7-14-21 | D14: 50 | E14: 7154
A15: BRN90 | B15: BRANCO 90G/M² | C15: 20-40-60 | D15: 90 | E15: 5843 | G15: Variação de - 15,97%
A16: CNP190 | B16: COUTING NEOPACK | C16: 20-40-60 | D16: 190 | E16: 7856.01
A17: KKN 150 | B17: KRAFT 150g | D17: 150 | E17: 5289.26 | G17: Variação de - 1,79%
A18: KKN 375 | B18: PAPEL KRAFT 375G | C18: 7-14-21 | D18: 375 | E18: 5708
A19: KKN080 | B19: KRAFT P/ ACOPLAGEM | C19: 7-14-21 | D19: 80 | E19: 7089
A20: KKN90 | B20: KRAFT | C20: 7-14-21 | D20: 100 | E20: 5289.26
A21: KKN100 | B21: KRAFT | C21: 7-14-21 | D21: 100 | E21: 5289.26
A22: KKN110 | B22: KRAFT | C22: 7-14-21 | D22: 115 | E22: 4896
A23: KKN125 | B23: KRAFT | C23: 7-14-21 | D23: 125 | E23: 5108
A24: KKN130 | B24: KRAFT | C24: 7-14-21 | D24: 125 | E24: 5108
A25: KKN140 | B25: KRAFT | C25: 7-14-21 | D25: 140 | E25: 5289.26
A26: KKN155 | B26: KRAFT 155 | D26: 155 | E26: 5289.26
A27: KKN160 | B27: KRAFT NORMAL 160g | C27: 7-14-21 | D27: 170 | E27: 5289.26
A28: KKN170 | B28: KRAFT NORMAL 170G | C28: 7-14-21 | D28: 180 | E28: 5289.26
A29: KKN175 | B29: KRAFT | C29: 7-14-21 | D29: 185 | E29: 5109
A30: KKN185 | B30: KRAFT | C30: 7-14-21 | D30: 185 | E30: 5109
A31: KKN190 | B31: KRAFT | C31: 7-14-21 | D31: 200 | E31: 5289.26
A32: KKN200 | B32: KRAFT | C32: 7-14-21 | D32: 200 | E32: 5289.26
A33: KKN240 | B33: KRAFT | C33: 7-14-21 | D33: 240 | E33: 5026
A34: KKN280 | B34: KRAFT 280 | C34: 7-14-21 | D34: 280 | E34: 7370
A35: KKP110 | B35: KRAFT 110g PLASTIFICADO (15g) | C35: 7-14-21 | D35: 130 | E35: =E36 -> 9170
A36: KKP125 | B36: KKN125(125g) + Plastif(15g) | C36: 7-14-21 | D36: 145 | E36: 9170
A37: MEN 190 | B37: MIOLO ESPECIAL 190 | C37: 7-14-21 | D37: 190 | E37: 3353 | G37: Variação de 0,58%
A38: MEN 350 | B38: MIOLO 350 GRAMAS ESPECIAL | C38: 7-14-21 | D38: 350 | E38: 3356.52
A39: MEN150 | B39: MIOLO RECICLADO | C39: 7-14-21 | D39: 150 | E39: 3317
A40: MEN165 | B40: MIOLO RECICLADO | C40: 7-14-21 | D40: 165 | E40: 3356.52
...

Sheet Abril-2023
A1: Papel | B1: Descrição | C1: Grupo | D1: Gramatura (g/m²) | E1: Custo ($/t)|Valor REAL
A2: 0 | B2: OUTROS | C2: 20-40-60 | D2: 1 | E2: 1
A3: BRN 056 | B3: BRANCO 56G/M² | C3: 7-14-21 | D3: 50 | E3: 6694.71
A4: BRN075 | B4: BRANCO 70g | D4: 75 | E4: =E3 -> 6694.71
A5: BRN075 | B5: BRANCO 75g | D5: 75 | E5: =E3 -> 6694.71
A6: BRN100 | C6: 7-14-21 | D6: 100 | E6: 0
A7: BRN110 | B7: Branco 110 | C7: 7-14-21 | D7: 110 | E7: 2960
A8: BRN120 | B8: BRANCO WTL | C8: 7-14-21 | D8: 120 | E8: 5943
A9: BRN130 | B9: BRANCO WTL | C9: 7-14-21 | D9: 120 | E9: 5902.73
A10: BRN140 | B10: BRANCO WTL | C10: 7-14-21 | D10: 140 | E10: 5394
A11: BRN150 | B11: BRANCO WTL | C11: 7-14-21 | D11: 150 | E11: 3070
A12: BRN175 | B12: BRANCO WTL KLABIN | C12: 7-14-21 | D12: 175 | E12: =6.296*1000 -> 6296 | G12: Variação de - 0,87%
A13: BRN180 | B13: BRANCO | C13: 7-14-21 | D13: 175 | E13: 6644.74
A14: BRN63 | B14: BRANCO | C14: 7-14-21 | D14: 50 | E14: 7154
A15: BRN90 | B15: BRANCO 90G/M² | C15: 20-40-60 | D15: 90 | E15: 5843 | G15: Variação de - 15,97%
A16: CNP190 | B16: COUTING NEOPACK | C16: 20-40-60 | D16: 190 | E16: 7856.01
A17: KKN 150 | B17: KRAFT 150g | D17: 150 | E17: 5289.26 | G17: Variação de - 1,79%
A18: KKN 375 | B18: PAPEL KRAFT 375G | C18: 7-14-21 | D18: 375 | E18: 5703
A19: KKN080 | B19: KRAFT P/ ACOPLAGEM | C19: 7-14-21 | D19: 80 | E19: 6280
A20: KKN90 | B20: KRAFT | C20: 7-14-21 | D20: 100 | E20: 5289.26
A21: KKN100 | B21: KRAFT | C21: 7-14-21 | D21: 100 | E21: 5289.26
A22: KKN110 | B22: KRAFT | C22: 7-14-21 | D22: 115 | E22: 4896
A23: KKN125 | B23: KRAFT | C23: 7-14-21 | D23: 125 | E23: 5190
A24: KKN130 | B24: KRAFT | C24: 7-14-21 | D24: 125 | E24: 5190
A25: KKN140 | B25: KRAFT | C25: 7-14-21 | D25: 140 | E25: 5289.26
A26: KKN155 | B26: KRAFT 155 | D26: 155 | E26: 5289.26
A27: KKN160 | B27: KRAFT NORMAL 160g | C27: 7-14-21 | D27: 170 | E27: 5289.26
A28: KKN170 | B28: KRAFT NORMAL 170G | C28: 7-14-21 | D28: 180 | E28: 5289.26
A29: KKN175 | B29: KRAFT | C29: 7-14-21 | D29: 185 | E29: 5230
A30: KKN185 | B30: KRAFT | C30: 7-14-21 | D30: 185 | E30: 5230
A31: KKN190 | B31: KRAFT | C31: 7-14-21 | D31: 200 | E31: 5289.26
A32: KKN200 | B32: KRAFT | C32: 7-14-21 | D32: 200 | E32: 5289.26
A33: KKN240 | B33: KRAFT | C33: 7-14-21 | D33: 240 | E33: 5026
A34: KKN280 | B34: KRAFT 280 | C34: 7-14-21 | D34: 280 | E34: 7370
A35: KKP110 | B35: KRAFT 110g PLASTIFICADO (15g) | C35: 7-14-21 | D35: 130 | E35: =E36 -> 9170
A36: KKP125 | B36: KKN125(125g) + Plastif(15g) | C36: 7-14-21 | D36: 145 | E36: 9170
A37: MEN 190 | B37: MIOLO ESPECIAL 190 | C37: 7-14-21 | D37: 190 | E37: 3270 | G37: Variação de 0,58%
A38: MEN 350 | B38: MIOLO 350 GRAMAS ESPECIAL | C38: 7-14-21 | D38: 350 | E38: 3356.52
A39: MEN150 | B39: MIOLO RECICLADO | C39: 7-14-21 | D39: 150 | E39: 3317
A40: MEN165 | B40: MIOLO RECICLADO | C40: 7-14-21 | D40: 165 | E40: 3356.52
...

Sheet Maio-2023
A1: Papel | B1: Descrição | C1: Grupo | D1: Gramatura (g/m²) | E1: Custo ($/t)|Valor REAL
A2: 0 | B2: OUTROS | C2: 20-40-60 | D2: 1 | E2: 1
A3: BRN 056 | B3: BRANCO 56G/M² | C3: 7-14-21 | D3: 50 | E3: 6694.71
A4: BRN075 | B4: BRANCO 70g | D4: 75 | E4: =E3 -> 6694.71
A5: BRN075 | B5: BRANCO 75g | D5: 75 | E5: =E3 -> 6694.71
A6: BRN100 | C6: 7-14-21 | D6: 100 | E6: 0
A7: BRN110 | B7: Branco 110 | C7: 7-14-21 | D7: 110 | E7: 2960
A8: BRN120 | B8: BRANCO WTL | C8: 7-14-21 | D8: 120 | E8: 5897 | G8: 5.897 | H8: =G8*1000 -> 5897
A9: BRN130 | B9: BRANCO WTL | C9: 7-14-21 | D9: 120 | E9: 5902.73
A10: BRN140 | B10: BRANCO WTL | C10: 7-14-21 | D10: 140 | E10: 5394
A11: BRN150 | B11: BRANCO WTL | C11: 7-14-21 | D11: 150 | E11: 5440
A12: BRN175 | B12: BRANCO WTL KLABIN | C12: 7-14-21 | D12: 175 | E12: =6.296*1000 -> 6296 | G12: Variação de - 0,87%
A13: BRN180 | B13: BRANCO | C13: 7-14-21 | D13: 175 | E13: 7796
A14: BRN63 | B14: BRANCO | C14: 7-14-21 | D14: 50 | E14: 7154
A15: BRN90 | B15: BRANCO 90G/M² | C15: 20-40-60 | D15: 90 | E15: 5843 | G15: Variação de - 15,97%
A16: CNP190 | B16: COUTING NEOPACK | C16: 20-40-60 | D16: 190 | E16: 7856.01
A17: KKN 150 | B17: KRAFT 150g | D17: 150 | E17: 5289.26 | G17: Variação de - 1,79%
A18: KKN 375 | B18: PAPEL KRAFT 375G | C18: 7-14-21 | D18: 375 | E18: 5588
A19: KKN080 | B19: KRAFT P/ ACOPLAGEM | C19: 7-14-21 | D19: 80 | E19: 6284
A20: KKN90 | B20: KRAFT | C20: 7-14-21 | D20: 100 | E20: 5289.26
A21: KKN100 | B21: KRAFT | C21: 7-14-21 | D21: 100 | E21: 5289.26
A22: KKN110 | B22: KRAFT | C22: 7-14-21 | D22: 115 | E22: 4896
A23: KKN125 | B23: KRAFT | C23: 7-14-21 | D23: 125 | E23: 5069
A24: KKN130 | B24: KRAFT | C24: 7-14-21 | D24: 125 | E24: 5190
A25: KKN140 | B25: KRAFT | C25: 7-14-21 | D25: 140 | E25: 5289.26
A26: KKN155 | B26: KRAFT 155 | D26: 155 | E26: 5289.26
A27: KKN160 | B27: KRAFT NORMAL 160g | C27: 7-14-21 | D27: 170 | E27: 5289.26
A28: KKN170 | B28: KRAFT NORMAL 170G | C28: 7-14-21 | D28: 180 | E28: 5289.26
A29: KKN175 | B29: KRAFT | C29: 7-14-21 | D29: 185 | E29: 5230
A30: KKN185 | B30: KRAFT | C30: 7-14-21 | D30: 185 | E30: 5174
A31: KKN190 | B31: KRAFT | C31: 7-14-21 | D31: 200 | E31: 5289.26
A32: KKN200 | B32: KRAFT | C32: 7-14-21 | D32: 200 | E32: 5289.26
A33: KKN240 | B33: KRAFT | C33: 7-14-21 | D33: 240 | E33: 5026
A34: KKN280 | B34: KRAFT 280 | C34: 7-14-21 | D34: 280 | E34: =7.004*1000 -> 7004
A35: KKP110 | B35: KRAFT 110g PLASTIFICADO (15g) | C35: 7-14-21 | D35: 130 | E35: =E36 -> 9170
A36: KKP125 | B36: KKN125(125g) + Plastif(15g) | C36: 7-14-21 | D36: 145 | E36: 9170
A37: MEN 190 | B37: MIOLO ESPECIAL 190 | C37: 7-14-21 | D37: 190 | E37: 3226 | G37: Variação de 0,58%
A38: MEN 350 | B38: MIOLO 350 GRAMAS ESPECIAL | C38: 7-14-21 | D38: 350 | E38: 3356.52
A39: MEN150 | B39: MIOLO RECICLADO | C39: 7-14-21 | D39: 150 | E39: 3127
A40: MEN165 | B40: MIOLO RECICLADO | C40: 7-14-21 | D40: 165 | E40: 3356.52
...

Sheet Junho-2023
A1: Papel | B1: Descrição | C1: Grupo | D1: Gramatura (g/m²) | E1: Custo ($/t)|Valor REAL
A2: 0 | B2: OUTROS | C2: 20-40-60 | D2: 1 | E2: 1
A3: BRN 056 | B3: BRANCO 56G/M² | C3: 7-14-21 | D3: 50 | E3: 6694.71 | G3: 6.69471 | H3: =G3*1000 -> 6694.71
A4: BRN075 | B4: BRANCO 70g | D4: 75 | E4: =E3 -> 6694.71
A5: BRN075 | B5: BRANCO 75g | D5: 75 | E5: =E3 -> 6694.71
A6: BRN100 | C6: 7-14-21 | D6: 100 | E6: 0
A7: BRN110 | B7: Branco 110 | C7: 7-14-21 | D7: 110 | E7: 2870
A8: BRN120 | B8: BRANCO WTL | C8: 7-14-21 | D8: 120 | E8: 5996 | G8: 5.897 | H8: =G8*1000 -> 5897
A9: BRN130 | B9: BRANCO WTL | C9: 7-14-21 | D9: 120 | E9: 5996
A10: BRN140 | B10: BRANCO WTL | C10: 7-14-21 | D10: 140 | E10: 5394
A11: BRN150 | B11: BRANCO WTL | C11: 7-14-21 | D11: 150 | E11: 5331
A12: BRN175 | B12: BRANCO WTL KLABIN | C12: 7-14-21 | D12: 175 | E12: =6.296*1000 -> 6296 | G12: Variação de - 0,87%
A13: BRN180 | B13: BRANCO | C13: 7-14-21 | D13: 175 | E13: 7796
A14: BRN63 | B14: BRANCO | C14: 7-14-21 | D14: 50 | E14: 7154
A15: BRN90 | B15: BRANCO 90G/M² | C15: 20-40-60 | D15: 90 | E15: 5843 | G15: Variação de - 15,97%
A16: CNP190 | B16: COUTING NEOPACK | C16: 20-40-60 | D16: 190 | E16: 7856.01
A17: KKN 150 | B17: KRAFT 150g | D17: 150 | E17: 5289.26 | G17: Variação de - 1,79%
A18: KKN 375 | B18: PAPEL KRAFT 375G | C18: 7-14-21 | D18: 375 | E18: 5853
A19: KKN080 | B19: KRAFT P/ ACOPLAGEM | C19: 7-14-21 | D19: 80 | E19: 6284
A20: KKN90 | B20: KRAFT | C20: 7-14-21 | D20: 100 | E20: 5289.26
A21: KKN100 | B21: KRAFT | C21: 7-14-21 | D21: 100 | E21: 5289.26
A22: KKN110 | B22: KRAFT | C22: 7-14-21 | D22: 115 | E22: 4896
A23: KKN125 | B23: KRAFT | C23: 7-14-21 | D23: 125 | E23: 5161
A24: KKN130 | B24: KRAFT | C24: 7-14-21 | D24: 125 | E24: 5190
A25: KKN140 | B25: KRAFT | C25: 7-14-21 | D25: 140 | E25: 5289.26
A26: KKN155 | B26: KRAFT 155 | D26: 155 | E26: 5289.26
A27: KKN160 | B27: KRAFT NORMAL 160g | C27: 7-14-21 | D27: 170 | E27: 5289.26
A28: KKN170 | B28: KRAFT NORMAL 170G | C28: 7-14-21 | D28: 180 | E28: 5289.26
A29: KKN175 | B29: KRAFT | C29: 7-14-21 | D29: 185 | E29: 5230
A30: KKN185 | B30: KRAFT | C30: 7-14-21 | D30: 185 | E30: 4958
A31: KKN190 | B31: KRAFT | C31: 7-14-21 | D31: 200 | E31: 5289.26
A32: KKN200 | B32: KRAFT | C32: 7-14-21 | D32: 200 | E32: 5289.26
A33: KKN240 | B33: KRAFT | C33: 7-14-21 | D33: 240 | E33: 5026
A34: KKN280 | B34: KRAFT 280 | C34: 7-14-21 | D34: 280 | E34: =7.004*1000 -> 7004
A35: KKP110 | B35: KRAFT 110g PLASTIFICADO (15g) | C35: 7-14-21 | D35: 130 | E35: =E36 -> 9170
A36: KKP125 | B36: KKN125(125g) + Plastif(15g) | C36: 7-14-21 | D36: 145 | E36: 9170
A37: MEN 190 | B37: MIOLO ESPECIAL 190 | C37: 7-14-21 | D37: 190 | E37: 3126 | G37: Variação de 0,58%
A38: MEN 350 | B38: MIOLO 350 GRAMAS ESPECIAL | C38: 7-14-21 | D38: 350 | E38: 3356.52
A39: MEN150 | B39: MIOLO RECICLADO | C39: 7-14-21 | D39: 150 | E39: 3058
A40: MEN165 | B40: MIOLO RECICLADO | C40: 7-14-21 | D40: 165 | E40: 3356.52
...

Sheet Julho-2023
A1: Papel | B1: Descrição | C1: Grupo | D1: Gramatura (g/m²) | E1: Custo ($/t)|Valor REAL
A2: 0 | B2: OUTROS | C2: 20-40-60 | D2: 1 | E2: 1
A3: BRN 056 | B3: BRANCO 56G/M² | C3: 7-14-21 | D3: 50 | E3: 6360 | G3: 6.36 | H3: =G3*1000 -> 6360
A4: BRN075 | B4: BRANCO 70g | D4: 75 | E4: =E3 -> 6360
A5: BRN075 | B5: BRANCO 75g | D5: 75 | E5: =E3 -> 6360
A6: BRN100 | C6: 7-14-21 | D6: 100 | E6: 0
A7: BRN110 | B7: Branco 110 | C7: 7-14-21 | D7: 110 | E7: 2640
A8: BRN120 | B8: BRANCO WTL | C8: 7-14-21 | D8: 120 | E8: 6000 | G8: 5.897 | H8: =G8*1000 -> 5897
A9: BRN130 | B9: BRANCO WTL | C9: 7-14-21 | D9: 120 | E9: 6000
A10: BRN140 | B10: BRANCO WTL | C10: 7-14-21 | D10: 140 | E10: 5394
A11: BRN150 | B11: BRANCO WTL | C11: 7-14-21 | D11: 150 | E11: 5330
A12: BRN175 | B12: BRANCO WTL KLABIN | C12: 7-14-21 | D12: 175 | E12: =6.296*1000 -> 6296 | G12: Variação de - 0,87%
A13: BRN180 | B13: BRANCO | C13: 7-14-21 | D13: 175 | E13: 7796
A14: BRN63 | B14: BRANCO | C14: 7-14-21 | D14: 50 | E14: 7154
A15: BRN90 | B15: BRANCO 90G/M² | C15: 20-40-60 | D15: 90 | E15: 5843 | G15: Variação de - 15,97%
A16: CNP190 | B16: COUTING NEOPACK | C16: 20-40-60 | D16: 190 | E16: 7856.01
A17: KKN 150 | B17: KRAFT 150g | D17: 150 | E17: 5289.26 | G17: Variação de - 1,79%
A18: KKN 375 | B18: PAPEL KRAFT 375G | C18: 7-14-21 | D18: 375 | E18: 3810
A19: KKN080 | B19: KRAFT P/ ACOPLAGEM | C19: 7-14-21 | D19: 80 | E19: 6120
A20: KKN90 | B20: KRAFT | C20: 7-14-21 | D20: 100 | E20: 5289.26
A21: KKN100 | B21: KRAFT | C21: 7-14-21 | D21: 100 | E21: 5289.26
A22: KKN110 | B22: KRAFT | C22: 7-14-21 | D22: 115 | E22: 4896
A23: KKN125 | B23: KRAFT | C23: 7-14-21 | D23: 125 | E23: 4630
A24: KKN130 | B24: KRAFT | C24: 7-14-21 | D24: 125 | E24: 5190
A25: KKN140 | B25: KRAFT | C25: 7-14-21 | D25: 140 | E25: 5289.26
A26: KKN155 | B26: KRAFT 155 | D26: 155 | E26: 5289.26
A27: KKN160 | B27: KRAFT NORMAL 160g | C27: 7-14-21 | D27: 170 | E27: 5289.26
A28: KKN170 | B28: KRAFT NORMAL 170G | C28: 7-14-21 | D28: 180 | E28: 5289.26
A29: KKN175 | B29: KRAFT | C29: 7-14-21 | D29: 185 | E29: 5230
A30: KKN185 | B30: KRAFT | C30: 7-14-21 | D30: 185 | E30: 4180
A31: KKN190 | B31: KRAFT | C31: 7-14-21 | D31: 200 | E31: 5289.26
A32: KKN200 | B32: KRAFT | C32: 7-14-21 | D32: 200 | E32: 5289.26
A33: KKN240 | B33: KRAFT | C33: 7-14-21 | D33: 240 | E33: 5026
A34: KKN280 | B34: KRAFT 280 | C34: 7-14-21 | D34: 280 | E34: =7000 -> 7000
A35: KKP110 | B35: KRAFT 110g PLASTIFICADO (15g) | C35: 7-14-21 | D35: 130 | E35: =E36 -> 9170
A36: KKP125 | B36: KKN125(125g) + Plastif(15g) | C36: 7-14-21 | D36: 145 | E36: 9170
A37: MEN 190 | B37: MIOLO ESPECIAL 190 | C37: 7-14-21 | D37: 190 | E37: 3070 | G37: Variação de 0,58%
A38: MEN 350 | B38: MIOLO 350 GRAMAS ESPECIAL | C38: 7-14-21 | D38: 350 | E38: 3356.52
A39: MEN150 | B39: MIOLO RECICLADO | C39: 7-14-21 | D39: 150 | E39: 2990
A40: MEN165 | B40: MIOLO RECICLADO | C40: 7-14-21 | D40: 165 | E40: 3356.52
...

Sheet Agosto-2023
A1: Papel | B1: Descrição | C1: Grupo | D1: Gramatura (g/m²) | E1: Custo ($/t)|Valor REAL
A2: 0 | B2: OUTROS | C2: 20-40-60 | D2: 1 | E2: 1
A3: BRN 056 | B3: BRANCO 56G/M² | C3: 7-14-21 | D3: 50 | E3: 6360 | G3: 6.36 | H3: =G3*1000 -> 6360
A4: BRN075 | B4: BRANCO 70g | D4: 75 | E4: =E3 -> 6360
A5: BRN075 | B5: BRANCO 75g | D5: 75 | E5: =E3 -> 6360
A6: BRN100 | C6: 7-14-21 | D6: 100 | E6: 0
A7: BRN110 | B7: Branco 110 | C7: 7-14-21 | D7: 110 | E7: 2660
A8: BRN120 | B8: BRANCO WTL | C8: 7-14-21 | D8: 120 | E8: 6000 | G8: 5.897 | H8: =G8*1000 -> 5897
A9: BRN130 | B9: BRANCO WTL | C9: 7-14-21 | D9: 120 | E9: 6000
A10: BRN140 | B10: BRANCO WTL | C10: 7-14-21 | D10: 140 | E10: 5394
A11: BRN150 | B11: BRANCO WTL | C11: 7-14-21 | D11: 150 | E11: 4472
A12: BRN175 | B12: BRANCO WTL KLABIN | C12: 7-14-21 | D12: 175 | E12: =6.296*1000 -> 6296 | G12: Variação de - 0,87%
A13: BRN180 | B13: BRANCO | C13: 7-14-21 | D13: 175 | E13: 7796
A14: BRN63 | B14: BRANCO | C14: 7-14-21 | D14: 50 | E14: 7154
A15: BRN90 | B15: BRANCO 90G/M² | C15: 20-40-60 | D15: 90 | E15: 5955 | G15: Variação de - 15,97%
A16: CNP190 | B16: COUTING NEOPACK | C16: 20-40-60 | D16: 190 | E16: 7856.01
A17: KKN 150 | B17: KRAFT 150g | D17: 150 | E17: 5289.26 | G17: Variação de - 1,79%
A18: KKN 375 | B18: PAPEL KRAFT 375G | C18: 7-14-21 | D18: 375 | E18: 3810
A19: KKN080 | B19: KRAFT P/ ACOPLAGEM | C19: 7-14-21 | D19: 80 | E19: 6284
A20: KKN90 | B20: KRAFT | C20: 7-14-21 | D20: 100 | E20: 5289.26
A21: KKN100 | B21: KRAFT | C21: 7-14-21 | D21: 100 | E21: 5289.26
A22: KKN110 | B22: KRAFT | C22: 7-14-21 | D22: 115 | E22: 4896
A23: KKN125 | B23: KRAFT | C23: 7-14-21 | D23: 125 | E23: 4656
A24: KKN130 | B24: KRAFT | C24: 7-14-21 | D24: 125 | E24: 5190
A25: KKN140 | B25: KRAFT | C25: 7-14-21 | D25: 140 | E25: 5289.26
A26: KKN155 | B26: KRAFT 155 | D26: 155 | E26: 5289.26
A27: KKN160 | B27: KRAFT NORMAL 160g | C27: 7-14-21 | D27: 170 | E27: 5289.26
A28: KKN170 | B28: KRAFT NORMAL 170G | C28: 7-14-21 | D28: 180 | E28: 5289.26
A29: KKN175 | B29: KRAFT | C29: 7-14-21 | D29: 185 | E29: 5230
A30: KKN185 | B30: KRAFT | C30: 7-14-21 | D30: 185 | E30: 4713
A31: KKN190 | B31: KRAFT | C31: 7-14-21 | D31: 200 | E31: 5289.26
A32: KKN200 | B32: KRAFT | C32: 7-14-21 | D32: 200 | E32: 5289.26
A33: KKN240 | B33: KRAFT | C33: 7-14-21 | D33: 240 | E33: 5026
A34: KKN280 | B34: KRAFT 280 | C34: 7-14-21 | D34: 280 | E34: =7000 -> 7000
A35: KKP110 | B35: KRAFT 110g PLASTIFICADO (15g) | C35: 7-14-21 | D35: 130 | E35: =E36 -> 9170
A36: KKP125 | B36: KKN125(125g) + Plastif(15g) | C36: 7-14-21 | D36: 145 | E36: 9170
A37: MEN 190 | B37: MIOLO ESPECIAL 190 | C37: 7-14-21 | D37: 190 | E37: 3142 | G37: Variação de 0,58%
A38: MEN 350 | B38: MIOLO 350 GRAMAS ESPECIAL | C38: 7-14-21 | D38: 350 | E38: 3356.52
A39: MEN150 | B39: MIOLO RECICLADO | C39: 7-14-21 | D39: 150 | E39: 3074
A40: MEN165 | B40: MIOLO RECICLADO | C40: 7-14-21 | D40: 165 | E40: 3356.52
...

Sheet Setembro-2023
A1: Papel | B1: Descrição | C1: Grupo | D1: Gramatura (g/m²) | E1: Custo ($/t)|Valor REAL
A2: 0 | B2: OUTROS | C2: 20-40-60 | D2: 1 | E2: 1
A3: BRN 056 | B3: BRANCO 56G/M² | C3: 7-14-21 | D3: 50 | E3: 6360 | G3: 6.36 | H3: =G3*1000 -> 6360
A4: BRN075 | B4: BRANCO 70g | D4: 75 | E4: =E3 -> 6360
A5: BRN075 | B5: BRANCO 75g | D5: 75 | E5: =E3 -> 6360
A6: BRN100 | C6: 7-14-21 | D6: 100 | E6: 0
A7: BRN110 | B7: Branco 110 | C7: 7-14-21 | D7: 110 | E7: 2639
A8: BRN120 | B8: BRANCO WTL | C8: 7-14-21 | D8: 120 | E8: 6000 | G8: 5.897 | H8: =G8*1000 -> 5897
A9: BRN130 | B9: BRANCO WTL | C9: 7-14-21 | D9: 120 | E9: 6000
A10: BRN140 | B10: BRANCO WTL | C10: 7-14-21 | D10: 140 | E10: 5394
A11: BRN150 | B11: BRANCO WTL | C11: 7-14-21 | D11: 150 | E11: 4221
A12: BRN175 | B12: BRANCO WTL KLABIN | C12: 7-14-21 | D12: 175 | E12: 7796 | G12: Variação de - 0,87%
A13: BRN180 | B13: BRANCO | C13: 7-14-21 | D13: 175 | E13: 7796
A14: BRN63 | B14: BRANCO | C14: 7-14-21 | D14: 50 | E14: 7154
A15: BRN90 | B15: BRANCO 90G/M² | C15: 20-40-60 | D15: 90 | E15: 5955 | G15: Variação de - 15,97%
A16: CNP190 | B16: COUTING NEOPACK | C16: 20-40-60 | D16: 190 | E16: 7796
A17: KKN 150 | B17: KRAFT 150g | D17: 150 | E17: 5289.26 | G17: Variação de - 1,79%
A18: KKN 375 | B18: PAPEL KRAFT 375G | C18: 7-14-21 | D18: 375 | E18: 5008
A19: KKN080 | B19: KRAFT P/ ACOPLAGEM | C19: 7-14-21 | D19: 80 | E19: 6422
A20: KKN90 | B20: KRAFT | C20: 7-14-21 | D20: 100 | E20: 5289.26
A21: KKN100 | B21: KRAFT | C21: 7-14-21 | D21: 100 | E21: 5289.26
A22: KKN110 | B22: KRAFT | C22: 7-14-21 | D22: 115 | E22: 3877
A23: KKN125 | B23: KRAFT | C23: 7-14-21 | D23: 125 | E23: 4781
A24: KKN130 | B24: KRAFT | C24: 7-14-21 | D24: 125 | E24: 5190
A25: KKN140 | B25: KRAFT | C25: 7-14-21 | D25: 140 | E25: 5289.26
A26: KKN155 | B26: KRAFT 155 | D26: 155 | E26: 5289.26
A27: KKN160 | B27: KRAFT NORMAL 160g | C27: 7-14-21 | D27: 170 | E27: 5289.26
A28: KKN170 | B28: KRAFT NORMAL 170G | C28: 7-14-21 | D28: 180 | E28: 5289.26
A29: KKN175 | B29: KRAFT | C29: 7-14-21 | D29: 185 | E29: 5230
A30: KKN185 | B30: KRAFT | C30: 7-14-21 | D30: 185 | E30: 4868
A31: KKN190 | B31: KRAFT | C31: 7-14-21 | D31: 200 | E31: 5289.26
A32: KKN200 | B32: KRAFT | C32: 7-14-21 | D32: 200 | E32: 5289.26
A33: KKN240 | B33: KRAFT | C33: 7-14-21 | D33: 240 | E33: 5026
A34: KKN280 | B34: KRAFT 280 | C34: 7-14-21 | D34: 280 | E34: 7004
A35: KKP110 | B35: KRAFT 110g PLASTIFICADO (15g) | C35: 7-14-21 | D35: 130 | E35: =E36 -> 9170
A36: KKP125 | B36: KKN125(125g) + Plastif(15g) | C36: 7-14-21 | D36: 145 | E36: 9170
A37: MEN 190 | B37: MIOLO ESPECIAL 190 | C37: 7-14-21 | D37: 190 | E37: 3115 | G37: Variação de 0,58%
A38: MEN 350 | B38: MIOLO 350 GRAMAS ESPECIAL | C38: 7-14-21 | D38: 350 | E38: 3356.52
A39: MEN150 | B39: MIOLO RECICLADO | C39: 7-14-21 | D39: 150 | E39: 2881
A40: MEN165 | B40: MIOLO RECICLADO | C40: 7-14-21 | D40: 165 | E40: 3356.52
...

Sheet Outubro-2023
A1: Papel | B1: Descrição | C1: Grupo | D1: Gramatura (g/m²) | E1: Custo ($/t)|Valor REAL
A2: 0 | B2: OUTROS | C2: 20-40-60 | D2: 1 | E2: 1
A3: BRN 056 | B3: BRANCO 56G/M² | C3: 7-14-21 | D3: 50 | E3: 6360 | G3: 6.36 | H3: =G3*1000 -> 6360
A4: BRN075 | B4: BRANCO 70g | D4: 75 | E4: =E3 -> 6360
A5: BRN075 | B5: BRANCO 75g | D5: 75 | E5: =E3 -> 6360
A6: BRN100 | C6: 7-14-21 | D6: 100 | E6: 0
A7: BRN110 | B7: Branco 110 | C7: 7-14-21 | D7: 110 | E7: 2649
A8: BRN120 | B8: BRANCO WTL | C8: 7-14-21 | D8: 120 | E8: 6000 | G8: 5.897 | H8: =G8*1000 -> 5897
A9: BRN130 | B9: BRANCO WTL | C9: 7-14-21 | D9: 120 | E9: 6000
A10: BRN140 | B10: BRANCO WTL | C10: 7-14-21 | D10: 140 | E10: 5394
A11: BRN150 | B11: BRANCO WTL | C11: 7-14-21 | D11: 150 | E11: 4222
A12: BRN175 | B12: BRANCO WTL KLABIN | C12: 7-14-21 | D12: 175 | E12: 4089 | G12: Variação de - 0,87%
A13: BRN180 | B13: BRANCO | C13: 7-14-21 | D13: 175 | E13: 7796
A14: BRN63 | B14: BRANCO | C14: 7-14-21 | D14: 50 | E14: 7154
A15: BRN90 | B15: BRANCO 90G/M² | C15: 20-40-60 | D15: 90 | E15: 6081 | G15: Variação de - 15,97%
A16: CNP190 | B16: COUTING NEOPACK | C16: 20-40-60 | D16: 190 | E16: 7796
A17: KKN 150 | B17: KRAFT 150g | D17: 150 | E17: 5289.26 | G17: Variação de - 1,79%
A18: KKN 375 | B18: PAPEL KRAFT 375G | C18: 7-14-21 | D18: 375 | E18: 4799
A19: KKN080 | B19: KRAFT P/ ACOPLAGEM | C19: 7-14-21 | D19: 80 | E19: 5930
A20: KKN90 | B20: KRAFT | C20: 7-14-21 | D20: 100 | E20: 5289.26
A21: KKN100 | B21: KRAFT | C21: 7-14-21 | D21: 100 | E21: 5289.26
A22: KKN110 | B22: KRAFT | C22: 7-14-21 | D22: 115 | E22: 3877
A23: KKN125 | B23: KRAFT | C23: 7-14-21 | D23: 125 | E23: 4565
A24: KKN130 | B24: KRAFT | C24: 7-14-21 | D24: 125 | E24: 5190
A25: KKN140 | B25: KRAFT | C25: 7-14-21 | D25: 140 | E25: 5289.26
A26: KKN155 | B26: KRAFT 155 | D26: 155 | E26: 5289.26
A27: KKN160 | B27: KRAFT NORMAL 160g | C27: 7-14-21 | D27: 170 | E27: 5289.26
A28: KKN170 | B28: KRAFT NORMAL 170G | C28: 7-14-21 | D28: 180 | E28: 5289.26
A29: KKN175 | B29: KRAFT | C29: 7-14-21 | D29: 185 | E29: 5230
A30: KKN185 | B30: KRAFT | C30: 7-14-21 | D30: 185 | E30: 4893
A31: KKN190 | B31: KRAFT | C31: 7-14-21 | D31: 200 | E31: 5289.26
A32: KKN200 | B32: KRAFT | C32: 7-14-21 | D32: 200 | E32: 5289.26
A33: KKN240 | B33: KRAFT | C33: 7-14-21 | D33: 240 | E33: 5026
A34: KKN280 | B34: KRAFT 280 | C34: 7-14-21 | D34: 280 | E34: 7004
A35: KKP110 | B35: KRAFT 110g PLASTIFICADO (15g) | C35: 7-14-21 | D35: 130 | E35: =E36 -> 9170
A36: KKP125 | B36: KKN125(125g) + Plastif(15g) | C36: 7-14-21 | D36: 145 | E36: 9170
A37: MEN 190 | B37: MIOLO ESPECIAL 190 | C37: 7-14-21 | D37: 190 | E37: 3114 | G37: Variação de 0,58%
A38: MEN 350 | B38: MIOLO 350 GRAMAS ESPECIAL | C38: 7-14-21 | D38: 350 | E38: 3356.52
A39: MEN150 | B39: MIOLO RECICLADO | C39: 7-14-21 | D39: 150 | E39: 2911
A40: MEN165 | B40: MIOLO RECICLADO | C40: 7-14-21 | D40: 165 | E40: 3356.52
...

Sheet Novembro-2023
A1: Papel | B1: Descrição | C1: Grupo | D1: Gramatura (g/m²) | E1: Custo ($/t)|Valor REAL
A2: 0 | B2: OUTROS | C2: 20-40-60 | D2: 1 | E2: 1
A3: BRN 056 | B3: BRANCO 56G/M² | C3: 7-14-21 | D3: 50 | E3: 6499 | G3: 6.36 | H3: =G3*1000 -> 6360
A4: BRN075 | B4: BRANCO 70g | D4: 75 | E4: =E3 -> 6499
A5: BRN075 | B5: BRANCO 75g | D5: 75 | E5: =E3 -> 6499
A6: BRN100 | C6: 7-14-21 | D6: 100 | E6: 0
A7: BRN110 | B7: Branco 110 | C7: 7-14-21 | D7: 110 | E7: 2659
A8: BRN120 | B8: BRANCO WTL | C8: 7-14-21 | D8: 120 | E8: 6000 | G8: 5.897 | H8: =G8*1000 -> 5897
A9: BRN130 | B9: BRANCO WTL | C9: 7-14-21 | D9: 120 | E9: 6000
A10: BRN140 | B10: BRANCO WTL | C10: 7-14-21 | D10: 140 | E10: 5394
A11: BRN150 | B11: BRANCO WTL | C11: 7-14-21 | D11: 150 | E11: 4222
A12: BRN175 | B12: BRANCO WTL KLABIN | C12: 7-14-21 | D12: 175 | E12: 4089 | G12: Variação de - 0,87%
A13: BRN180 | B13: BRANCO | C13: 7-14-21 | D13: 175 | E13: 7796
A14: BRN63 | B14: BRANCO | C14: 7-14-21 | D14: 50 | E14: 7154
A15: BRN90 | B15: BRANCO 90G/M² | C15: 20-40-60 | D15: 90 | E15: 6081 | G15: Variação de - 15,97%
A16: CNP190 | B16: COUTING NEOPACK | C16: 20-40-60 | D16: 190 | E16: 7232
A17: KKN 150 | B17: KRAFT 150g | D17: 150 | E17: 5289.26 | G17: Variação de - 1,79%
A18: KKN 375 | B18: PAPEL KRAFT 375G | C18: 7-14-21 | D18: 375 | E18: 5008
A19: KKN080 | B19: KRAFT P/ ACOPLAGEM | C19: 7-14-21 | D19: 80 | E19: 5930
A20: KKN90 | B20: KRAFT | C20: 7-14-21 | D20: 100 | E20: 4222
A21: KKN100 | B21: KRAFT | C21: 7-14-21 | D21: 100 | E21: 5289.26
A22: KKN110 | B22: KRAFT | C22: 7-14-21 | D22: 115 | E22: 3877
A23: KKN125 | B23: KRAFT | C23: 7-14-21 | D23: 125 | E23: 4461
A24: KKN130 | B24: KRAFT | C24: 7-14-21 | D24: 125 | E24: 5190
A25: KKN140 | B25: KRAFT | C25: 7-14-21 | D25: 140 | E25: 5289.26
A26: KKN155 | B26: KRAFT 155 | D26: 155 | E26: 5289.26
A27: KKN160 | B27: KRAFT NORMAL 160g | C27: 7-14-21 | D27: 170 | E27: 5289.26
A28: KKN170 | B28: KRAFT NORMAL 170G | C28: 7-14-21 | D28: 180 | E28: 5289.26
A29: KKN175 | B29: KRAFT | C29: 7-14-21 | D29: 185 | E29: 5230
A30: KKN185 | B30: KRAFT | C30: 7-14-21 | D30: 185 | E30: 5008
A31: KKN190 | B31: KRAFT | C31: 7-14-21 | D31: 200 | E31: 5289.26
A32: KKN200 | B32: KRAFT | C32: 7-14-21 | D32: 200 | E32: 5289.26
A33: KKN240 | B33: KRAFT | C33: 7-14-21 | D33: 240 | E33: 5026
A34: KKN280 | B34: KRAFT 280 | C34: 7-14-21 | D34: 280 | E34: 7004
A35: KKP110 | B35: KRAFT 110g PLASTIFICADO (15g) | C35: 7-14-21 | D35: 130 | E35: =E36 -> 9170
A36: KKP125 | B36: KKN125(125g) + Plastif(15g) | C36: 7-14-21 | D36: 145 | E36: 9170
A37: MEN 190 | B37: MIOLO ESPECIAL 190 | C37: 7-14-21 | D37: 190 | E37: 3138 | G37: Variação de 0,58%
A38: MEN 350 | B38: MIOLO 350 GRAMAS ESPECIAL | C38: 7-14-21 | D38: 350 | E38: 3356.52
A39: MEN150 | B39: MIOLO RECICLADO | C39: 7-14-21 | D39: 150 | E39: 2871
A40: MEN165 | B40: MIOLO RECICLADO | C40: 7-14-21 | D40: 165 | E40: 3356.52
...

Sheet Dezembro-2023
A1: Papel | B1: Descrição | C1: Grupo | D1: Gramatura (g/m²) | E1: Custo ($/t)|Valor REAL
A2: 0 | B2: OUTROS | C2: 20-40-60 | D2: 1 | E2: 1
A3: BRN 056 | B3: BRANCO 56G/M² | C3: 7-14-21 | D3: 50 | E3: 6499 | G3: 6.36 | H3: =G3*1000 -> 6360
A4: BRN075 | B4: BRANCO 70g | D4: 75 | E4: =E3 -> 6499
A5: BRN075 | B5: BRANCO 75g | D5: 75 | E5: =E3 -> 6499
A6: BRN100 | C6: 7-14-21 | D6: 100 | E6: 0
A7: BRN110 | B7: Branco 110 | C7: 7-14-21 | D7: 110 | E7: 2554
A8: BRN120 | B8: BRANCO WTL | C8: 7-14-21 | D8: 120 | E8: 6000 | G8: 5.897 | H8: =G8*1000 -> 5897
A9: BRN130 | B9: BRANCO WTL | C9: 7-14-21 | D9: 120 | E9: 6000
A10: BRN140 | B10: BRANCO WTL | C10: 7-14-21 | D10: 140 | E10: 5394
A11: BRN150 | B11: BRANCO WTL | C11: 7-14-21 | D11: 150 | E11: 4222
A12: BRN175 | B12: BRANCO WTL KLABIN | C12: 7-14-21 | D12: 175 | E12: 4222 | G12: Variação de - 0,87%
A13: BRN180 | B13: BRANCO | C13: 7-14-21 | D13: 175 | E13: 7796
A14: BRN63 | B14: BRANCO | C14: 7-14-21 | D14: 50 | E14: 7154
A15: BRN90 | B15: BRANCO 90G/M² | C15: 20-40-60 | D15: 90 | E15: 6081 | G15: Variação de - 15,97%
A16: CNP190 | B16: COUTING NEOPACK | C16: 20-40-60 | D16: 190 | E16: 7232
A17: KKN 150 | B17: KRAFT 150g | D17: 150 | E17: 5289.26 | G17: Variação de - 1,79%
A18: KKN 375 | B18: PAPEL KRAFT 375G | C18: 7-14-21 | D18: 375 | E18: 4850
A19: KKN080 | B19: KRAFT P/ ACOPLAGEM | C19: 7-14-21 | D19: 80 | E19: 5747
A20: KKN90 | B20: KRAFT | C20: 7-14-21 | D20: 100 | E20: 4222
A21: KKN100 | B21: KRAFT | C21: 7-14-21 | D21: 100 | E21: 5289.26
A22: KKN110 | B22: KRAFT | C22: 7-14-21 | D22: 115 | E22: 3877
A23: KKN125 | B23: KRAFT | C23: 7-14-21 | D23: 125 | E23: 4762
A24: KKN130 | B24: KRAFT | C24: 7-14-21 | D24: 125 | E24: 5190
A25: KKN140 | B25: KRAFT | C25: 7-14-21 | D25: 140 | E25: 4135
A26: KKN155 | B26: KRAFT 155 | D26: 155 | E26: 5289.26
A27: KKN160 | B27: KRAFT NORMAL 160g | C27: 7-14-21 | D27: 170 | E27: 4902
A28: KKN170 | B28: KRAFT NORMAL 170G | C28: 7-14-21 | D28: 180 | E28: 5289.26
A29: KKN175 | B29: KRAFT | C29: 7-14-21 | D29: 185 | E29: 5230
A30: KKN185 | B30: KRAFT | C30: 7-14-21 | D30: 185 | E30: 4932
A31: KKN190 | B31: KRAFT | C31: 7-14-21 | D31: 200 | E31: 5289.26
A32: KKN200 | B32: KRAFT | C32: 7-14-21 | D32: 200 | E32: 5289.26
A33: KKN240 | B33: KRAFT | C33: 7-14-21 | D33: 240 | E33: 5026
A34: KKN280 | B34: KRAFT 280 | C34: 7-14-21 | D34: 280 | E34: 7004
A35: KKP110 | B35: KRAFT 110g PLASTIFICADO (15g) | C35: 7-14-21 | D35: 130 | E35: =E36 -> 9170
A36: KKP125 | B36: KKN125(125g) + Plastif(15g) | C36: 7-14-21 | D36: 145 | E36: 9170
A37: MEN 190 | B37: MIOLO ESPECIAL 190 | C37: 7-14-21 | D37: 190 | E37: 3150 | G37: Variação de 0,58%
A38: MEN 350 | B38: MIOLO 350 GRAMAS ESPECIAL | C38: 7-14-21 | D38: 350 | E38: 3356.52
A39: MEN150 | B39: MIOLO RECICLADO | C39: 7-14-21 | D39: 150 | E39: 2795
A40: MEN165 | B40: MIOLO RECICLADO | C40: 7-14-21 | D40: 165 | E40: 3356.52
...

Sheet Janeiro-2024
A1: Papel | B1: Descrição | C1: Grupo | D1: Gramatura (g/m²) | E1: Custo ($/t)|Valor REAL
A2: 0 | B2: OUTROS | C2: 20-40-60 | D2: 1 | E2: 1
A3: BRN 056 | B3: BRANCO 56G/M² | C3: 7-14-21 | D3: 50 | E3: 6499 | G3: 6.36 | H3: =G3*1000 -> 6360
A4: BRN075 | B4: BRANCO 70g | D4: 75 | E4: =E3 -> 6499
A5: BRN075 | B5: BRANCO 75g | D5: 75 | E5: =E3 -> 6499
A6: BRN100 | C6: 7-14-21 | D6: 100 | E6: 0
A7: BRN110 | B7: Branco 110 | C7: 7-14-21 | D7: 110 | E7: 2518
A8: BRN120 | B8: BRANCO WTL | C8: 7-14-21 | D8: 120 | E8: 6000 | G8: 5.897 | H8: =G8*1000 -> 5897
A9: BRN130 | B9: BRANCO WTL | C9: 7-14-21 | D9: 120 | E9: 6000
A10: BRN140 | B10: BRANCO WTL | C10: 7-14-21 | D10: 140 | E10: 5394
A11: BRN150 | B11: BRANCO WTL | C11: 7-14-21 | D11: 150 | E11: 4179
A12: BRN175 | B12: BRANCO WTL KLABIN | C12: 7-14-21 | D12: 175 | E12: 4179 | G12: Variação de - 0,87%
A13: BRN180 | B13: BRANCO | C13: 7-14-21 | D13: 175 | E13: 7796
A14: BRN63 | B14: BRANCO | C14: 7-14-21 | D14: 50 | E14: 7154
A15: BRN90 | B15: BRANCO 90G/M² | C15: 20-40-60 | D15: 90 | E15: 5699 | G15: Variação de - 15,97%
A16: CNP190 | B16: COUTING NEOPACK | C16: 20-40-60 | D16: 190 | E16: 7232
A17: KKN 150 | B17: KRAFT 150g | D17: 150 | E17: 5289.26 | G17: Variação de - 1,79%
A18: KKN 375 | B18: PAPEL KRAFT 375G | C18: 7-14-21 | D18: 375 | E18: 4700
A19: KKN080 | B19: KRAFT P/ ACOPLAGEM | C19: 7-14-21 | D19: 80 | E19: 5747
A20: KKN90 | B20: KRAFT | C20: 7-14-21 | D20: 100 | E20: 4222
A21: KKN100 | B21: KRAFT | C21: 7-14-21 | D21: 100 | E21: 5289.26
A22: KKN110 | B22: KRAFT | C22: 7-14-21 | D22: 115 | E22: 3877
A23: KKN125 | B23: KRAFT | C23: 7-14-21 | D23: 125 | E23: 4627
A24: KKN130 | B24: KRAFT | C24: 7-14-21 | D24: 125 | E24: 5190
A25: KKN140 | B25: KRAFT | C25: 7-14-21 | D25: 140 | E25: 4179
A26: KKN155 | B26: KRAFT 155 | D26: 155 | E26: 5289.26
A27: KKN160 | B27: KRAFT NORMAL 160g | C27: 7-14-21 | D27: 170 | E27: 4902
A28: KKN170 | B28: KRAFT NORMAL 170G | C28: 7-14-21 | D28: 180 | E28: 5289.26
A29: KKN175 | B29: KRAFT | C29: 7-14-21 | D29: 185 | E29: 5230
A30: KKN185 | B30: KRAFT | C30: 7-14-21 | D30: 185 | E30: 4874
A31: KKN190 | B31: KRAFT | C31: 7-14-21 | D31: 200 | E31: 5289.26
A32: KKN200 | B32: KRAFT | C32: 7-14-21 | D32: 200 | E32: 5289.26
A33: KKN240 | B33: KRAFT | C33: 7-14-21 | D33: 240 | E33: 5026
A34: KKN280 | B34: KRAFT 280 | C34: 7-14-21 | D34: 280 | E34: 7004
A35: KKP110 | B35: KRAFT 110g PLASTIFICADO (15g) | C35: 7-14-21 | D35: 130 | E35: =E36 -> 8046.47
A36: KKP125 | B36: KKN125(125g) + Plastif(15g) | C36: 7-14-21 | D36: 145 | E36: 8046.47
A37: MEN 190 | B37: MIOLO ESPECIAL 190 | C37: 7-14-21 | D37: 190 | E37: 2990 | G37: Variação de 0,58%
A38: MEN 350 | B38: MIOLO 350 GRAMAS ESPECIAL | C38: 7-14-21 | D38: 350 | E38: 3356.52
A39: MEN150 | B39: MIOLO RECICLADO | C39: 7-14-21 | D39: 150 | E39: 2968
A40: MEN165 | B40: MIOLO RECICLADO | C40: 7-14-21 | D40: 165 | E40: 3356.52
...

Sheet Fevereiro-2024
A1: Papel | B1: Descrição | C1: Grupo | D1: Gramatura (g/m²) | E1: Custo ($/t)|Valor REAL
A2: 0 | B2: OUTROS | C2: 20-40-60 | D2: 1 | E2: 1
A3: BRN 056 | B3: BRANCO 56G/M² | C3: 7-14-21 | D3: 50 | E3: 6499 | G3: 6.36 | H3: =G3*1000 -> 6360
A4: BRN075 | B4: BRANCO 70g | D4: 75 | E4: =E3 -> 6499
A5: BRN075 | B5: BRANCO 75g | D5: 75 | E5: =E3 -> 6499
A6: BRN100 | C6: 7-14-21 | D6: 100 | E6: 0
A7: BRN110 | B7: Branco 110 | C7: 7-14-21 | D7: 110 | E7: 2623
A8: BRN120 | B8: BRANCO WTL | C8: 7-14-21 | D8: 120 | E8: 6000 | G8: 5.897 | H8: =G8*1000 -> 5897
A9: BRN130 | B9: BRANCO WTL | C9: 7-14-21 | D9: 120 | E9: 6000
A10: BRN140 | B10: BRANCO WTL | C10: 7-14-21 | D10: 140 | E10: 5394
A11: BRN150 | B11: BRANCO WTL | C11: 7-14-21 | D11: 150 | E11: 3496
A12: BRN175 | B12: BRANCO WTL KLABIN | C12: 7-14-21 | D12: 175 | E12: 4179 | G12: Variação de - 0,87%
A13: BRN180 | B13: BRANCO | C13: 7-14-21 | D13: 175 | E13: 7796
A14: BRN63 | B14: BRANCO | C14: 7-14-21 | D14: 50 | E14: 7154
A15: BRN90 | B15: BRANCO 90G/M² | C15: 20-40-60 | D15: 90 | E15: 5699 | G15: Variação de - 15,97%
A16: CNP190 | B16: COUTING NEOPACK | C16: 20-40-60 | D16: 190 | E16: 7547
A17: KKN 150 | B17: KRAFT 150g | D17: 150 | E17: 5289.26 | G17: Variação de - 1,79%
A18: KKN 375 | B18: PAPEL KRAFT 375G | C18: 7-14-21 | D18: 375 | E18: 4843
A19: KKN080 | B19: KRAFT P/ ACOPLAGEM | C19: 7-14-21 | D19: 80 | E19: 5747
A20: KKN90 | B20: KRAFT | C20: 7-14-21 | D20: 100 | E20: 4222
A21: KKN100 | B21: KRAFT | C21: 7-14-21 | D21: 100 | E21: 5289.26
A22: KKN110 | B22: KRAFT | C22: 7-14-21 | D22: 115 | E22: 3877
A23: KKN125 | B23: KRAFT | C23: 7-14-21 | D23: 125 | E23: 4525
A24: KKN130 | B24: KRAFT | C24: 7-14-21 | D24: 125 | E24: 5190
A25: KKN140 | B25: KRAFT | C25: 7-14-21 | D25: 140 | E25: 4421
A26: KKN155 | B26: KRAFT 155 | D26: 155 | E26: 5289.26
A27: KKN160 | B27: KRAFT NORMAL 160g | C27: 7-14-21 | D27: 170 | E27: 4902
A28: KKN170 | B28: KRAFT NORMAL 170G | C28: 7-14-21 | D28: 180 | E28: 5289.26
A29: KKN175 | B29: KRAFT | C29: 7-14-21 | D29: 185 | E29: 5230
A30: KKN185 | B30: KRAFT | C30: 7-14-21 | D30: 185 | E30: 4965
A31: KKN190 | B31: KRAFT | C31: 7-14-21 | D31: 200 | E31: 5289.26
A32: KKN200 | B32: KRAFT | C32: 7-14-21 | D32: 200 | E32: 5289.26
A33: KKN240 | B33: KRAFT | C33: 7-14-21 | D33: 240 | E33: 5026
A34: KKN280 | B34: KRAFT 280 | C34: 7-14-21 | D34: 280 | E34: 7004
A35: KKP110 | B35: KRAFT 110g PLASTIFICADO (15g) | C35: 7-14-21 | D35: 130 | E35: =E36 -> 8046.03
A36: KKP125 | B36: KKN125(125g) + Plastif(15g) | C36: 7-14-21 | D36: 145 | E36: =8.04603*1000 -> 8046.03
A37: MEN 190 | B37: MIOLO ESPECIAL 190 | C37: 7-14-21 | D37: 190 | E37: 2913 | G37: Variação de 0,58%
A38: MEN 350 | B38: MIOLO 350 GRAMAS ESPECIAL | C38: 7-14-21 | D38: 350 | E38: 3356.52
A39: MEN150 | B39: MIOLO RECICLADO | C39: 7-14-21 | D39: 150 | E39: 2911
A40: MEN165 | B40: MIOLO RECICLADO | C40: 7-14-21 | D40: 165 | E40: 3356.52
...

Sheet Março-2024
A1: Papel | B1: Descrição | C1: Grupo | D1: Gramatura (g/m²) | E1: Custo ($/t)|Valor REAL
A2: 0 | B2: OUTROS | C2: 20-40-60 | D2: 1 | E2: 1
A3: BRN 056 | B3: BRANCO 56G/M² | C3: 7-14-21 | D3: 50 | E3: 6499 | G3: 6.36 | H3: =G3*1000 -> 6360
A4: BRN075 | B4: BRANCO 70g | D4: 75 | E4: =E3 -> 6499
A5: BRN075 | B5: BRANCO 75g | D5: 75 | E5: =E3 -> 6499
A6: BRN100 | C6: 7-14-21 | D6: 100 | E6: 0
A7: BRN110 | B7: Branco 110 | C7: 7-14-21 | D7: 110 | E7: 2445
A8: BRN120 | B8: BRANCO WTL | C8: 7-14-21 | D8: 120 | E8: 3326 | G8: 5.897 | H8: =G8*1000 -> 5897
A9: BRN130 | B9: BRANCO WTL | C9: 7-14-21 | D9: 120 | E9: 3326
A10: BRN140 | B10: BRANCO WTL | C10: 7-14-21 | D10: 140 | E10: 5394
A11: BRN150 | B11: BRANCO WTL | C11: 7-14-21 | D11: 150 | E11: 3326
A12: BRN175 | B12: BRANCO WTL KLABIN | C12: 7-14-21 | D12: 175 | E12: 3326 | G12: Variação de - 0,87%
A13: BRN180 | B13: BRANCO | C13: 7-14-21 | D13: 175 | E13: 7796
A14: BRN63 | B14: BRANCO | C14: 7-14-21 | D14: 50 | E14: 7154
A15: BRN90 | B15: BRANCO 90G/M² | C15: 20-40-60 | D15: 90 | E15: 5465 | G15: Variação de - 15,97%
A16: CNP190 | B16: COUTING NEOPACK | C16: 20-40-60 | D16: 190 | E16: 7547
A17: KKN 150 | B17: KRAFT 150g | D17: 150 | E17: 5289.26 | G17: Variação de - 1,79%
A18: KKN 375 | B18: PAPEL KRAFT 375G | C18: 7-14-21 | D18: 375 | E18: 5008
A19: KKN080 | B19: KRAFT P/ ACOPLAGEM | C19: 7-14-21 | D19: 80 | E19: 5747
A20: KKN90 | B20: KRAFT | C20: 7-14-21 | D20: 100 | E20: 4222
A21: KKN100 | B21: KRAFT | C21: 7-14-21 | D21: 100 | E21: 5289.26
A22: KKN110 | B22: KRAFT | C22: 7-14-21 | D22: 115 | E22: 3877
A23: KKN125 | B23: KRAFT | C23: 7-14-21 | D23: 125 | E23: 4222
A24: KKN130 | B24: KRAFT | C24: 7-14-21 | D24: 125 | E24: 5190
A25: KKN140 | B25: KRAFT | C25: 7-14-21 | D25: 140 | E25: 4421
A26: KKN155 | B26: KRAFT 155 | D26: 155 | E26: 5289.26
A27: KKN160 | B27: KRAFT NORMAL 160g | C27: 7-14-21 | D27: 170 | E27: 4902
