Workbook

Sheet Extrato Mensal Jan
A2: REIS DO NORDESTE CAMA MESA E BANHO LTDA | B2: 05697368000174 | C2: CAMILA SILVA MOTA | D2: VENDEDOR (A) | E2: 72 | F2: Trabalhando | G2: 42438 | H2: 220:00 | I2: Salário: | J2: 1388.5
A3: REIS DO NORDESTE CAMA MESA E BANHO LTDA | B3: 05697368000174 | C3: CAMILA SILVA MOTA | D3: VENDEDOR (A) | E3: 72 | F3: Trabalhando | G3: 42438 | H3: 220:00 | I3: DESC.ADIANT.SALARIAL | J3: 555.4
A4: REIS DO NORDESTE CAMA MESA E BANHO LTDA | B4: 05697368000174 | C4: CAMILA SILVA MOTA | D4: VENDEDOR (A) | E4: 72 | F4: Trabalhando | G4: 42438 | H4: 220:00 | I4: I.N.S.S. | J4: 119.28
A5: REIS DO NORDESTE CAMA MESA E BANHO LTDA | B5: 05697368000174 | C5: CAMILA SILVA MOTA | D5: VENDEDOR (A) | E5: 72 | F5: Trabalhando | G5: 42438 | H5: 220:00 | I5: TRIENIO SINDCOMFS | J5: 138.85
A6: REIS DO NORDESTE CAMA MESA E BANHO LTDA | B6: 05697368000174 | C6: CAMILA SILVA MOTA | D6: VENDEDOR (A) | E6: 72 | F6: Trabalhando | G6: 42438 | H6: 220:00 | I6: VALES | J6: 29.99
A7: REIS DO NORDESTE CAMA MESA E BANHO LTDA | B7: 05697368000174 | C7: CAMILA SILVA MOTA | D7: VENDEDOR (A) | E7: 72 | F7: Trabalhando | G7: 42438 | H7: 220:00 | I7: VALE TRANSPORTE 6% | J7: 83.31
A8: REIS DO NORDESTE CAMA MESA E BANHO LTDA | B8: 05697368000174 | C8: ELIANE DOS SANTOS SILVA | D8: VENDEDOR (A) | E8: 100 | F8: Trabalhando | G8: 44117 | H8: 220:00 | I8: Salário: | J8: 1388.5
A9: REIS DO NORDESTE CAMA MESA E BANHO LTDA | B9: 05697368000174 | C9: ELIANE DOS SANTOS SILVA | D9: VENDEDOR (A) | E9: 100 | F9: Trabalhando | G9: 44117 | H9: 220:00 | I9: DESC.ADIANT.SALARIAL | J9: 555.4
A10: REIS DO NORDESTE CAMA MESA E BANHO LTDA | B10: 05697368000174 | C10: ELIANE DOS SANTOS SILVA | D10: VENDEDOR (A) | E10: 100 | F10: Trabalhando | G10: 44117 | H10: 220:00 | I10: I.N.S.S. | J10: 106.78
A11: REIS DO NORDESTE CAMA MESA E BANHO LTDA | B11: 05697368000174 | C11: ELIANE DOS SANTOS SILVA | D11: VENDEDOR (A) | E11: 100 | F11: Trabalhando | G11: 44117 | H11: 220:00 | I11: SALARIO FAMILIA | J11: 56.47
A12: REIS DO NORDESTE CAMA MESA E BANHO LTDA | B12: 05697368000174 | C12: ELIANE DOS SANTOS SILVA | D12: VENDEDOR (A) | E12: 100 | F12: Trabalhando | G12: 44117 | H12: 220:00 | I12: VALES | J12: 153.26
A13: REIS DO NORDESTE CAMA MESA E BANHO LTDA | B13: 05697368000174 | C13: ELIANE DOS SANTOS SILVA | D13: VENDEDOR (A) | E13: 100 | F13: Trabalhando | G13: 44117 | H13: 220:00 | I13: VALE TRANSPORTE 6% | J13: 83.31
... A592: REIS DO NORDESTE CAMA MESA E BANHO LTDA | B592: 05697368000336 | C592: VERONICA SANTOS DA SILVA | D592: COSTUREIRO ( A ) | E592: 145 | F592: Trabalhando | G592: 43497 | H592: 205:20 | I592: I.N.S.S. | J592: 90.9

Sheet Resumo
A1: SITUAÇÃO | B1: (Vários itens)
A2: Função | B2: (Vários itens)
A4: Rótulos de Linha | B4: SALARIO COM IMPOSTOS | C4: SALARIO BASE 2 | D4: BENEFICIOS | E4: VALE COMPRAS TOTAIS
A5: 5K DECORAÇÕES | B5: 6037.148 | C5: 1660 | D5: 99.6 | E5: 0 | G5: 6037.148 | H5: =G5-B5 -> 0
A6: GENESIS | B6: 31524.468 | C6: 500 | D6: 298.4 | E6: 101.99 | G6: 31524.468 | H6: =G6-B6 -> 0
A7: HOME CENTER | B7: 14455.508 | C7: 275 | D7: 139.2 | E7: 477 | G7: 14455.508 | H7: =G7-B7 -> 0
A8: MAISON | B8: 11647.063 | C8: 0 | D8: 238.86 | E8: 0 | G8: 11647.063 | H8: =G8-B8 -> 0
A9: ESCRITORIO | B9: 35779.316 | C9: 8156.364 | D9: 39.89 | E9: 126.78 | G9: 35779.316 | H9: =G9-B9 -> 0
A10: FABRICA | B10: 143386.03 | C10: 17011.62 | D10: 0 | E10: 0 | G10: 143386.03 | H10: =G10-B10 -> 0
A11: 30 K | B11: 16072.112 | C11: 632 | D11: -304.43 | E11: 299.67 | G11: 16072.112 | H11: =G11-B11 -> 0
A12: GRAND CANYON | B12: 12225.324 | C12: 2777 | D12: 0 | E12: 0 | G12: 12225.324 | H12: =G12-B12 -> 0
A13: 10k DECORAÇÕES | B13: 13049.936 | C13: 100 | D13: 0 | E13: 100 | G13: 13049.936 | H13: =G13-B13 -> 0
A14: AVANTE | B14: 12518.032 | C14: 0 | D14: -138 | E14: 188.27 | G14: 12518.032 | H14: =G14-B14 -> 0
A15: METANÓIA | B15: 11545.316 | C15: 0 | D15: 0 | E15: 0 | G15: 11545.316 | H15: =G15-B15 -> 0
A16: SR PASSOS | B16: 35640.921 | C16: 5275 | D16: 1452.55 | E16: 206.38 | G16: 43997.766 | H16: =G16-B16 -> 8356.8447
A17: 15 K COMERCIAL | B17: 10658.524 | C17: 0 | D17: -80 | E17: 360.42 | G17: 10658.524 | H17: =G17-B17 -> 0
A18: Total Geral | B18: 354539.69 | C18: 36386.984 | D18: 1746.07 | E18: 1860.51
G23: 0.01
G24: 0.08 | H24: =G24+G23 -> 0.09 | I24: =(H24-H23)/H23 -> #DIV/0!
G25: 0.28 | H25: =G25+H24 -> 0.37 | I25: =(H25-H24)/H24 -> 3.1111111
G26: 3.96 | H26: =G26+H25 -> 4.33 | I26: =(H26-H25)/H25 -> 10.702703
G27: 8.58 | H27: =G27+H26 -> 12.91 | I27: =(H27-H26)/H26 -> 1.9815242
G28: 7.21 | H28: =G28+H27 -> 20.12 | I28: =(H28-H27)/H27 -> 0.5584818
G29: 7.51 | H29: =G29+H28 -> 27.63 | I29: =(H29-H28)/H28 -> 0.37326044
G30: 8.1 | H30: =G30+H29 -> 35.73 | I30: =(H30-H29)/H29 -> 0.29315961
G31: 7.91 | H31: =G31+H30 -> 43.64 | I31: =(H31-H30)/H30 -> 0.22138259
G32: 9.07 | H32: =G32+H31 -> 52.71 | I32: =(H32-H31)/H31 -> 0.20783685
G33: 10.48 | H33: =G33+H32 -> 63.19 | I33: =(H33-H32)/H32 -> 0.19882375
G34: 11.85 | H34: =G34+H33 -> 75.04 | I34: =(H34-H33)/H33 -> 0.18752967
G35: 12.67 | H35: =G35+H34 -> 87.71 | I35: =(H35-H34)/H34 -> 0.16884328
G36: 16.35 | H36: =G36+H35 -> 104.06 | I36: =(H36-H35)/H35 -> 0.18640976
... G38: 18.63 | H38: =G38+H37 -> 138.69 | I38: =(H38-H37)/H37 -> 0.15517241
G39: 23.56 | H39: =G39+H38 -> 162.25 | I39: =(G39-G38)/G38 -> 0.26462695
G40: 24.32 | H40: =G40+H39 -> 186.57 | I40: =(G40-G39)/G39 -> 0.032258065
G44: =SUM(G23:G43) -> 186.57

Sheet GRATIFICAÇÃO
A1: COLABORADOR | B1: Função | C1: Razão Social | D1: Alocação | E1: Origem | F1: Valor Total | G1: Coluna1
A2: EDISLEY DA CONCEICAO | B2: FISCAL DE LOJA | C2: 05K | D2: REIS MATRIZ | E2: GRATIFICAÇÃO | F2: 300 | G2: =SUMIF(BASE_DE_NOMES[Nome],GRATIFICAÇÃO[[#This Row],[COLABORADOR]],BASE_DE_NOMES[GRATIFICAÇÃO])-GRATIFICAÇÃO[[#This Row],[Valor Total]] -> -300
A3: DANILO RIBEIRO SANTANA | B3: SERV.GERAIS | C3: REIS MATRIZ | D3: GENESIS | E3: GRATIFICAÇÃO | F3: 200 | G3: =SUMIF(BASE_DE_NOMES[Nome],GRATIFICAÇÃO[[#This Row],[COLABORADOR]],BASE_DE_NOMES[GRATIFICAÇÃO])-GRATIFICAÇÃO[[#This Row],[Valor Total]] -> 0
A4: DORIVALDO SANTOS ARAUJO | B4: CONFERENTE | C4: RAINHA HOME | D4: RAINHA HOME | E4: GRATIFICAÇÃO | F4: 275 | G4: =SUMIF(BASE_DE_NOMES[Nome],GRATIFICAÇÃO[[#This Row],[COLABORADOR]],BASE_DE_NOMES[GRATIFICAÇÃO])-GRATIFICAÇÃO[[#This Row],[Valor Total]] -> 0
A5: GILBERTO GALDINO DOS SANTOS | B5: SERVIÇOS GERAIS | C5: 10K | D5: 10K | E5: GRATIFICAÇÃO | F5: 100 | G5: =SUMIF(BASE_DE_NOMES[Nome],GRATIFICAÇÃO[[#This Row],[COLABORADOR]],BASE_DE_NOMES[GRATIFICAÇÃO])-GRATIFICAÇÃO[[#This Row],[Valor Total]] -> 0
A6: HEMILENE SOUZA RIBEIRO | B6: ASSIST FINAN | C6: REIS MATRIZ | D6: ESCRITÓRIO | E6: GRATIFICAÇÃO | F6: 300 | G6: =SUMIF(BASE_DE_NOMES[Nome],GRATIFICAÇÃO[[#This Row],[COLABORADOR]],BASE_DE_NOMES[GRATIFICAÇÃO])-GRATIFICAÇÃO[[#This Row],[Valor Total]] -> 0
A7: JOÃO VICTOR DE SOUZA | B7: SERVIÇOS GERAIS | C7: 05K | D7: RAINHA MAISON | E7: GRATIFICAÇÃO | F7: 150 | G7: =SUMIF(BASE_DE_NOMES[Nome],GRATIFICAÇÃO[[#This Row],[COLABORADOR]],BASE_DE_NOMES[GRATIFICAÇÃO])-GRATIFICAÇÃO[[#This Row],[Valor Total]] -> -150
A8: LEILANA FELICIANO SANTANA | B8: GERENTE | C8: GRAND CANYON | D8: GRAND CANYON | E8: GRATIFICAÇÃO | F8: 500 | G8: =SUMIF(BASE_DE_NOMES[Nome],GRATIFICAÇÃO[[#This Row],[COLABORADOR]],BASE_DE_NOMES[GRATIFICAÇÃO])-GRATIFICAÇÃO[[#This Row],[Valor Total]] -> 0
A9: NATERCIO PEREIRA SANTANA | B9: MOTORISTA | C9: REIS FABRICA | D9: REIS FABRICA | E9: GRATIFICAÇÃO | F9: 539 | G9: =SUMIF(BASE_DE_NOMES[Nome],GRATIFICAÇÃO[[#This Row],[COLABORADOR]],BASE_DE_NOMES[GRATIFICAÇÃO])-GRATIFICAÇÃO[[#This Row],[Valor Total]] -> 0
A10: UELITON DA SILVA DE JESUS | B10: SERVICOS GERAIS | C10: REIS MATRIZ | D10: REIS MATRIZ | E10: GRATIFICAÇÃO | F10: 300 | G10: =SUMIF(BASE_DE_NOMES[Nome],GRATIFICAÇÃO[[#This Row],[COLABORADOR]],BASE_DE_NOMES[GRATIFICAÇÃO])-GRATIFICAÇÃO[[#This Row],[Valor Total]] -> 0
A11: ALESSANDRO BATISTA DA ROCHA | B11: EMBALADOR | C11: REIS FÁBRICA | D11: REIS FÁBRICA | E11: GRATIFICAÇÃO | F11: 200 | G11: =SUMIF(BASE_DE_NOMES[Nome],GRATIFICAÇÃO[[#This Row],[COLABORADOR]],BASE_DE_NOMES[GRATIFICAÇÃO])-GRATIFICAÇÃO[[#This Row],[Valor Total]] -> 0
A12: ALBERTO DO NASCIMENTO SANTOS | B12: EMBALADOR | C12: REIS FÁBRICA | D12: REIS FÁBRICA | E12: GRATIFICAÇÃO | F12: 100 | G12: =SUMIF(BASE_DE_NOMES[Nome],GRATIFICAÇÃO[[#This Row],[COLABORADOR]],BASE_DE_NOMES[GRATIFICAÇÃO])-GRATIFICAÇÃO[[#This Row],[Valor Total]] -> 0
A13: FAGNER OLIVEIRA DOS SANTOS | B13: COORDENADOR | C13: VALE XEL | D13: VALE XEL | E13: GRATIFICAÇÃO | F13: 700 | G13: =SUMIF(BASE_DE_NOMES[Nome],GRATIFICAÇÃO[[#This Row],[COLABORADOR]],BASE_DE_NOMES[GRATIFICAÇÃO])-GRATIFICAÇÃO[[#This Row],[Valor Total]] -> 0
... A26: WILLIAM NASCIMENTO DOS SANTOS | B26: COSTUREIRO | C26: REIS FÁBRICA | D26: REIS FÁBRICA | E26: GRATIFICAÇÃO | F26: 200 | G26: =SUMIF(BASE_DE_NOMES[Nome],GRATIFICAÇÃO[[#This Row],[COLABORADOR]],BASE_DE_NOMES[GRATIFICAÇÃO])-GRATIFICAÇÃO[[#This Row],[Valor Total]] -> 0
F27: =SUBTOTAL(109,GRATIFICAÇÃO[Valor Total]) -> 7195 | G27: =SUBTOTAL(109,GRATIFICAÇÃO[Coluna1]) -> -1350

Sheet Salários Resumo (3)
A4: Situação | B4: (Vários itens)
A6: Soma de Total
A7: #NAME?

Sheet PG
A1: Nome | B1: Função | C1: Razão Social | D1: Alocação | E1: Valor Pago | F1: Coluna1
A2: DENIFER SANTOS DO NASCIMENTO - 15/05 | B2: APRENDIZ | C2: REIS FABRICA | D2: REIS FABRICA | E2: 379.5 | F2: =SUMIF(BASE_DE_NOMES[Nome],PG[[#This Row],[Nome]],BASE_DE_NOMES[PAGAMENTOS])-PG[[#This Row],[Valor Pago]] -> -379.5
A3: EDUARDA RODRIGUES | B3: APRENDIZ | C3: REIS FABRICA | D3: REIS FABRICA | E3: 1518 | F3: =SUMIF(BASE_DE_NOMES[Nome],PG[[#This Row],[Nome]],BASE_DE_NOMES[PAGAMENTOS])-PG[[#This Row],[Valor Pago]] -> -1518
A4: FERNANDA SANTOS | B4: APRENDIZ | C4: REIS FABRICA | D4: REIS FABRICA | E4: 759 | F4: =SUMIF(BASE_DE_NOMES[Nome],PG[[#This Row],[Nome]],BASE_DE_NOMES[PAGAMENTOS])-PG[[#This Row],[Valor Pago]] -> -759
A5: GILBERTO DOS SANTOS | B5: SUPERVISOR | C5: SEM REGISTRO | D5: REIS MATRIZ | E5: 5275 | F5: =SUMIF(BASE_DE_NOMES[Nome],PG[[#This Row],[Nome]],BASE_DE_NOMES[PAGAMENTOS])-PG[[#This Row],[Valor Pago]] -> 0
A6: ICAELLE NASCIMENTO GONZAGA | B6: APRENDIZ | C6: REIS FABRICA | D6: REIS FABRICA | E6: 759 | F6: =SUMIF(BASE_DE_NOMES[Nome],PG[[#This Row],[Nome]],BASE_DE_NOMES[PAGAMENTOS])-PG[[#This Row],[Valor Pago]] -> -759
A7: ISAC MORENO MENEZES MELO | B7: ASSIST. ADM | C7: SEM REGISTRO | D7: ESCRITORIO | E7: 2110 | F7: =SUMIF(BASE_DE_NOMES[Nome],PG[[#This Row],[Nome]],BASE_DE_NOMES[PAGAMENTOS])-PG[[#This Row],[Valor Pago]] -> 0
A8: IVONISE CARVALHO | B8: SERV GERAIS | C8: SEM REGISTRO | D8: ESCRITORIO | E8: 1016.474 | F8: =SUMIF(BASE_DE_NOMES[Nome],PG[[#This Row],[Nome]],BASE_DE_NOMES[PAGAMENTOS])-PG[[#This Row],[Valor Pago]] -> 0
A9: JILMAN DOS SANTOS | B9: GERENTE | C9: REIS FABRICA | D9: REIS FABRICA | E9: 821.44 | F9: =SUMIF(BASE_DE_NOMES[Nome],PG[[#This Row],[Nome]],BASE_DE_NOMES[PAGAMENTOS])-PG[[#This Row],[Valor Pago]] -> 0
A10: JOSE GABRIEL SANTOS SILVA | B10: APRENDIZ | C10: REIS FABRICA | D10: REIS FABRICA | E10: 759 | F10: =SUMIF(BASE_DE_NOMES[Nome],PG[[#This Row],[Nome]],BASE_DE_NOMES[PAGAMENTOS])-PG[[#This Row],[Valor Pago]] -> -759
A11: JOSE SOARES DOS SANTOS | B11: VIGIA | C11: REIS FABRICA | D11: REIS FABRICA | E11: 600 | F11: =SUMIF(BASE_DE_NOMES[Nome],PG[[#This Row],[Nome]],BASE_DE_NOMES[PAGAMENTOS])-PG[[#This Row],[Valor Pago]] -> -600
A12: JOÃO ANTONIO CUZ SANTANA | B12: APRENDIZ | C12: REIS FABRICA | D12: REIS FABRICA | E12: 759 | F12: =SUMIF(BASE_DE_NOMES[Nome],PG[[#This Row],[Nome]],BASE_DE_NOMES[PAGAMENTOS])-PG[[#This Row],[Valor Pago]] -> -759
A13: JULIA VILANOVA CANDIDO - 23/05 | B13: APRENDIZ | C13: REIS FABRICA | D13: REIS FABRICA | E13: 202.4 | F13: =SUMIF(BASE_DE_NOMES[Nome],PG[[#This Row],[Nome]],BASE_DE_NOMES[PAGAMENTOS])-PG[[#This Row],[Valor Pago]] -> -202.4
... A24: ROSILENE ROCHA DA SILVA - 16/05 | B24: APRENDIZ | C24: REIS FABRICA | D24: REIS FABRICA | E24: 354.2 | F24: =SUMIF(BASE_DE_NOMES[Nome],PG[[#This Row],[Nome]],BASE_DE_NOMES[PAGAMENTOS])-PG[[#This Row],[Valor Pago]] -> -354.2
A25: SHIRLEY CERQUEIRA PINTO | C25: SEM REGISTRO | D25: ESCRITORIO | E25: 3666.66 | F25: =SUMIF(BASE_DE_NOMES[Nome],PG[[#This Row],[Nome]],BASE_DE_NOMES[PAGAMENTOS])-PG[[#This Row],[Valor Pago]] -> 0
A26: VANDERSON LINO SANTOS | B26: APRENDIZ | C26: REIS FABRICA | D26: REIS FABRICA | E26: 50.6 | F26: =SUMIF(BASE_DE_NOMES[Nome],PG[[#This Row],[Nome]],BASE_DE_NOMES[PAGAMENTOS])-PG[[#This Row],[Valor Pago]] -> -50.6
A27: WALLAS FERREIRA DE SANTANA - 16/05 | B27: APRENDIZ | C27: REIS FABRICA | D27: REIS FABRICA | E27: 354.2 | F27: =SUMIF(BASE_DE_NOMES[Nome],PG[[#This Row],[Nome]],BASE_DE_NOMES[PAGAMENTOS])-PG[[#This Row],[Valor Pago]] -> -354.2
A28: WELLINGTON RIBEIRO | B28: COSTUREIRO | C28: SEM REGISTRO | D28: REIS FABRICA | E28: 1518 | F28: =SUMIF(BASE_DE_NOMES[Nome],PG[[#This Row],[Nome]],BASE_DE_NOMES[PAGAMENTOS])-PG[[#This Row],[Valor Pago]] -> -1518
E29: =SUBTOTAL(109,PG[Valor Pago]) -> 7590 | F29: =SUBTOTAL(109,PG[Coluna1]) -> -7590
H47: 0

Sheet Demitidos
A1: Index | B1: Column3 | C1: Column1
A2: 622 | B2: RAYANE MONTEIRO REIS | C2: 45746
A3: 655 | B3: VERONICA JESUS DOS SANTOS | C3: 45718
A4: 1393 | B4: COSMINHA PEREIRA COELHO | C4: 45718
A5: 1565 | B5: TAIUANA SANTOS SOARES | C5: 45718
A6: 1579 | B6: GILBERTO DOS SANTOS | C6: 45718
A7: 1593 | B7: IVONISE CARVALHO DE JESUS | C7: 45718
A8: 1612 | B8: JOELMA SILVA SANTOS | C8: 45718
A9: 1628 | B9: LAVINIA REIS DE LIMA | C9: 45718

Sheet BASE DE NOMES
A1: Nome | B1: Função | C1: Razão Social | D1: Alocações | E1: Admissão | F1: SITUAÇÃO | G1: C.CHEQUE | H1: FALTAS | I1: DESCONTO | J1: TOTAL DE C.CHEQUE | K1: GRATIFICAÇÃO | L1: PAGAMENTOS | M1: TOTAL DE QUEBRA | N1: ADC. ANTIGUIDADE | O1: TOTAL DE TRIENIO | P1: TX ASSIS. TOTAL | Q1: FAMILIA | R1: BOLSA DE AUXILIO | S1: VALE TRANSP | T1: PLANO DE SAUDE | U1: DESCONTOS | V1: BENEFICIOS | W1: VALE COMPRAS TOTAIS | X1: CCT | Y1: SALARIO BASE | Z1: SALARIO BASE 2 | AA1: IMPOSTOS | AB1: SALARIO COM IMPOSTOS | AC1: NOME2 | AD1: NOME3
A2: ADRIANA CLEIDE ALVES | B2: CAIXA | C2: 10K | D2: 10K | E2: =IFERROR(_xlfn.XLOOKUP(BASE_DE_NOMES[[#This Row],[Nome]],'Folha Rainha'!B:B,'Folha Rainha'!D:D),0) -> 0 | F2: =IFERROR(_xlfn.XLOOKUP(BASE_DE_NOMES[[#This Row],[Nome]],'Folha Rainha'!B:B,'Folha Rainha'!E:E)," ") | G2: =SUMIFS('Folha Rainha'!G:G,'Folha Rainha'!B:B,BASE_DE_NOMES[[#This Row],[Nome]],'Folha Rainha'!F:F,"Salário Base")+SUMIFS('Folha Rainha'!G:G,'Folha Rainha'!B:B,BASE_DE_NOMES[[#This Row],[Nome]],'Folha Rainha'!F:F,"Salário:") -> 0 | H2: =SUMIFS('Folha Rainha'!G:G,'Folha Rainha'!B:B,BASE_DE_NOMES[[#This Row],[Nome]],'Folha Rainha'!F:F,"HORAS FALTAS PARCIAL")+SUMIFS('Folha Rainha'!G:G,'Folha Rainha'!B:B,BASE_DE_NOMES[[#This Row],[Nome]],'Folha Rainha'!F:F,"HORAS FALTAS")+SUMIFS('Folha Rainha'!G:G,'Folha Rainha'!B:B,BASE_DE_NOMES[[#This Row],[Nome]],'Folha Rainha'!F:F,"HORAS FALTAS DSR")+SUMIFS('Folha Rainha'!G:G,'Folha Rainha'!B:B,BASE_DE_NOMES[[#This Row],[Nome]],'Folha Rainha'!F:F,"FALTA DE CAIXA") -> 0 | I2: =SUMIFS('Folha Rainha'!G:G,'Folha Rainha'!B:B,BASE_DE_NOMES[[#This Row],[Nome]],'Folha Rainha'!F:F,"DESCONTO HORAS AFASTADAS")+SUMIFS('Folha Rainha'!G:G,'Folha Rainha'!B:B,BASE_DE_NOMES[[#This Row],[Nome]],'Folha Rainha'!F:F,"DESCONTO HORAS AFASTADAS ACID TRABALHO")+SUMIFS('Folha Rainha'!G:G,'Folha Rainha'!B:B,BASE_DE_NOMES[[#This Row],[Nome]],'Folha Rainha'!F:F,"SALARIO MATERNIDADE") -> 0 | J2: =BASE_DE_NOMES[[#This Row],[C.CHEQUE]]-BASE_DE_NOMES[[#This Row],[FALTAS]]-BASE_DE_NOMES[[#This Row],[DESCONTO ]] -> 0 | K2: =SUMIF(GRATIFICAÇÃO!A:A,BASE_DE_NOMES[[#This Row],[Nome]],GRATIFICAÇÃO!F:F) -> 0 | L2: =SUMIF(PG!A:A,BASE_DE_NOMES[[#This Row],[Nome]],PG!E:E) -> 0 | M2: =SUMIFS('Folha Rainha'!G:G,'Folha Rainha'!B:B,BASE_DE_NOMES[[#This Row],[Nome]],'Folha Rainha'!F:F,"*Quebra*",'Folha Rainha'!F:F,"*QUEBRA*") -> 0 | N2: =SUMIFS('Folha Rainha'!G:G,'Folha Rainha'!B:B,BASE_DE_NOMES[[#This Row],[Nome]],'Folha Rainha'!F:F,"ADC. ANTIGUIDADE") -> 0 | O2: =SUMIFS('Folha Rainha'!G:G,'Folha Rainha'!B:B,BASE_DE_NOMES[[#This Row],[Nome]],'Folha Rainha'!F:F,"*Trienio*") -> 0 | P2: =SUMIFS('Folha Rainha'!G:G,'Folha Rainha'!B:B,BASE_DE_NOMES[[#This Row],[Nome]],'Folha Rainha'!F:F,"*TAXA*") -> 0 | Q2: =SUMIFS('Folha Rainha'!G:G,'Folha Rainha'!B:B,BASE_DE_NOMES[[#This Row],[Nome]],'Folha Rainha'!F:F,"SALARIO FAMILIA")+SUMIFS('Folha Rainha'!G:G,'Folha Rainha'!B:B,BASE_DE_NOMES[[#This Row],[Nome]],'Folha Rainha'!F:F,"Salário Família") -> 0 | R2: =SUMIFS('Folha Rainha'!G:G,'Folha Rainha'!B:B,BASE_DE_NOMES[[#This Row],[Nome]],'Folha Rainha'!F:F,"BOLSA AUXILIO")+SUMIFS('Folha Rainha'!G:G,'Folha Rainha'!B:B,BASE_DE_NOMES[[#This Row],[Nome]],'Folha Rainha'!F:F,"BOLSA AUXILIO AFASTAMENTO DIREITOS INT") -> 0 | S2: =SUMIFS('Folha Rainha'!G:G,'Folha Rainha'!B:B,BASE_DE_NOMES[[#This Row],[Nome]],'Folha Rainha'!F:F,"Vale Transporte")+SUMIFS('Folha Rainha'!G:G,'Folha Rainha'!B:B,BASE_DE_NOMES[[#This Row],[Nome]],'Folha Rainha'!F:F,"VALE TRANSPORTE 6%")+SUMIFS('Folha Rainha'!G:G,'Folha Rainha'!B:B,BASE_DE_NOMES[[#This Row],[Nome]],'Folha Rainha'!F:F,"AUXILIO TRANSPORTE ") -> 0 | T2: =SUMIFS('Folha Rainha'!G:G,'Folha Rainha'!B:B,BASE_DE_NOMES[[#This Row],[Nome]],'Folha Rainha'!F:F,"ASSISTÊNCIA ODONTOLÓGICA")+SUMIFS('Folha Rainha'!G:G,'Folha Rainha'!B:B,BASE_DE_NOMES[[#This Row],[Nome]],'Folha Rainha'!F:F,"ASSIST. ODONTO OUTROS DEPENDENTES")+SUMIFS('Folha Rainha'!G:G,'Folha Rainha'!B:B,BASE_DE_NOMES[[#This Row],[Nome]],'Folha Rainha'!F:F,"AUXILIO PLANO DE BENEFICIOS DEPENDENTES ") -> 0 | U2: =SUMIFS('Folha Rainha'!G:G,'Folha Rainha'!B:B,BASE_DE_NOMES[[#This Row],[Nome]],'Folha Rainha'!F:F,"BOLSA AUXILIO DESCONTO ADIANTAMENTO")+SUMIFS('Folha Rainha'!G:G,'Folha Rainha'!B:B,BASE_DE_NOMES[[#This Row],[Nome]],'Folha Rainha'!F:F,"DESCONTO PLANO DE SAÚDE")+BASE_DE_NOMES[[#This Row],[TX ASSIS. TOTAL]] -> 0 | V2: =BASE_DE_NOMES[[#This Row],[BOLSA DE AUXILIO]]+BASE_DE_NOMES[[#This Row],[VALE TRANSP]]+BASE_DE_NOMES[[#This Row],[PLANO DE SAUDE]]-BASE_DE_NOMES[[#This Row],[DESCONTOS]] -> 0 | W2: =SUMIFS('Folha Rainha'!G:G,'Folha Rainha'!B:B,BASE_DE_NOMES[[#This Row],[Nome]],'Folha Rainha'!F:F,"VALE COMPRAS")+SUMIFS('Folha Rainha'!G:G,'Folha Rainha'!B:B,BASE_DE_NOMES[[#This Row],[Nome]],'Folha Rainha'!F:F,"VALES") -> 0 | X2: =SUMIFS('Folha Rainha'!G:G,'Folha Rainha'!B:B,BASE_DE_NOMES[[#This Row],[Nome]],'Folha Rainha'!F:F,"ABONO CCT SECOFS 2024-2025")+SUMIFS('Folha Rainha'!G:G,'Folha Rainha'!B:B,BASE_DE_NOMES[[#This Row],[Nome]],'Folha Rainha'!F:F,"PARCELA DIFERENÇA 13o CCT")+SUMIFS('Folha Rainha'!G:G,'Folha Rainha'!B:B,BASE_DE_NOMES[[#This Row],[Nome]],'Folha Rainha'!F:F,"CONTRIBUICAO ABONO CCT 2024-2025") -> 0 | Y2: =BASE_DE_NOMES[[#This Row],[TOTAL DE C.CHEQUE]]+BASE_DE_NOMES[[#This Row],[TOTAL DE QUEBRA]]+BASE_DE_NOMES[[#This Row],[ADC. ANTIGUIDADE]]+BASE_DE_NOMES[[#This Row],[TOTAL DE TRIENIO]]+BASE_DE_NOMES[[#This Row],[CCT]] -> 0 | Z2: =BASE_DE_NOMES[[#This Row],[PAGAMENTOS]]+BASE_DE_NOMES[[#This Row],[GRATIFICAÇÃO]] -> 0 | AA2: =_xlfn.XLOOKUP(BASE_DE_NOMES[[#This Row],[NOME2]],Planilha1!C:C,Planilha1!D:D)*Y2 -> 0 | AB2: =BASE_DE_NOMES[[#This Row],[IMPOSTOS]]+BASE_DE_NOMES[[#This Row],[SALARIO BASE]]+BASE_DE_NOMES[[#This Row],[FAMILIA]] -> 0 | AC2: =_xlfn.XLOOKUP(BASE_DE_NOMES[[#This Row],[Razão Social]],Planilha1!B:B,Planilha1!C:C) -> 10k DECORAÇÕES | AD2: =_xlfn.XLOOKUP(BASE_DE_NOMES[[#This Row],[Alocações]],Planilha1!B:B,Planilha1!C:C) -> 10k DECORAÇÕES
A3: ADRIANE AMORIM RIBEIRO | B3: VENDEDOR | C3: GENESIS | D3: REIS MTZ | E3: =IFERROR(_xlfn.XLOOKUP(BASE_DE_NOMES[[#This Row],[Nome]],'Folha Rainha'!B:B,'Folha Rainha'!D:D),0) -> 0 | F3: =IFERROR(_xlfn.XLOOKUP(BASE_DE_NOMES[[#This Row],[Nome]],'Folha Rainha'!B:B,'Folha Rainha'!E:E)," ") | G3: =SUMIFS('Folha Rainha'!G:G,'Folha Rainha'!B:B,BASE_DE_NOMES[[#This Row],[Nome]],'Folha Rainha'!F:F,"Salário Base")+SUMIFS('Folha Rainha'!G:G,'Folha Rainha'!B:B,BASE_DE_NOMES[[#This Row],[Nome]],'Folha Rainha'!F:F,"Salário:") -> 0 | H3: =SUMIFS('Folha Rainha'!G:G,'Folha Rainha'!B:B,BASE_DE_NOMES[[#This Row],[Nome]],'Folha Rainha'!F:F,"HORAS FALTAS PARCIAL")+SUMIFS('Folha Rainha'!G:G,'Folha Rainha'!B:B,BASE_DE_NOMES[[#This Row],[Nome]],'Folha Rainha'!F:F,"HORAS FALTAS")+SUMIFS('Folha Rainha'!G:G,'Folha Rainha'!B:B,BASE_DE_NOMES[[#This Row],[Nome]],'Folha Rainha'!F:F,"HORAS FALTAS DSR")+SUMIFS('Folha Rainha'!G:G,'Folha Rainha'!B:B,BASE_DE_NOMES[[#This Row],[Nome]],'Folha Rainha'!F:F,"FALTA DE CAIXA") -> 0 | I3: =SUMIFS('Folha Rainha'!G:G,'Folha Rainha'!B:B,BASE_DE_NOMES[[#This Row],[Nome]],'Folha Rainha'!F:F,"DESCONTO HORAS AFASTADAS")+SUMIFS('Folha Rainha'!G:G,'Folha Rainha'!B:B,BASE_DE_NOMES[[#This Row],[Nome]],'Folha Rainha'!F:F,"DESCONTO HORAS AFASTADAS ACID TRABALHO")+SUMIFS('Folha Rainha'!G:G,'Folha Rainha'!B:B,BASE_DE_NOMES[[#This Row],[Nome]],'Folha Rainha'!F:F,"SALARIO MATERNIDADE") -> 0 | J3: =BASE_DE_NOMES[[#This Row],[C.CHEQUE]]-BASE_DE_NOMES[[#This Row],[FALTAS]]-BASE_DE_NOMES[[#This Row],[DESCONTO ]] -> 0 | K3: =SUMIF(GRATIFICAÇÃO!A:A,BASE_DE_NOMES[[#This Row],[Nome]],GRATIFICAÇÃO!F:F) -> 0 | L3: =SUMIF(PG!A:A,BASE_DE_NOMES[[#This Row],[Nome]],PG!E:E) -> 0 | M3: =SUMIFS('Folha Rainha'!G:G,'Folha Rainha'!B:B,BASE_DE_NOMES[[#This Row],[Nome]],'Folha Rainha'!F:F,"*Quebra*",'Folha Rainha'!F:F,"*QUEBRA*") -> 0 | N3: =SUMIFS('Folha Rainha'!G:G,'Folha Rainha'!B:B,BASE_DE_NOMES[[#This Row],[Nome]],'Folha Rainha'!F:F,"ADC. ANTIGUIDADE") -> 0 | O3: =SUMIFS('Folha Rainha'!G:G,'Folha Rainha'!B:B,BASE_DE_NOMES[[#This Row],[Nome]],'Folha Rainha'!F:F,"*Trienio*") -> 0 | P3: =SUMIFS('Folha Rainha'!G:G,'Folha Rainha'!B:B,BASE_DE_NOMES[[#This Row],[Nome]],'Folha Rainha'!F:F,"*TAXA*") -> 0 | Q3: =SUMIFS('Folha Rainha'!G:G,'Folha Rainha'!B:B,BASE_DE_NOMES[[#This Row],[Nome]],'Folha Rainha'!F:F,"SALARIO FAMILIA")+SUMIFS('Folha Rainha'!G:G,'Folha Rainha'!B:B,BASE_DE_NOMES[[#This Row],[Nome]],'Folha Rainha'!F:F,"Salário Família") -> 0 | R3: =SUMIFS('Folha Rainha'!G:G,'Folha Rainha'!B:B,BASE_DE_NOMES[[#This Row],[Nome]],'Folha Rainha'!F:F,"BOLSA AUXILIO")+SUMIFS('Folha Rainha'!G:G,'Folha Rainha'!B:B,BASE_DE_NOMES[[#This Row],[Nome]],'Folha Rainha'!F:F,"BOLSA AUXILIO AFASTAMENTO DIREITOS INT") -> 0 | S3: =SUMIFS('Folha Rainha'!G:G,'Folha Rainha'!B:B,BASE_DE_NOMES[[#This Row],[Nome]],'Folha Rainha'!F:F,"Vale Transporte")+SUMIFS('Folha Rainha'!G:G,'Folha Rainha'!B:B,BASE_DE_NOMES[[#This Row],[Nome]],'Folha Rainha'!F:F,"VALE TRANSPORTE 6%")+SUMIFS('Folha Rainha'!G:G,'Folha Rainha'!B:B,BASE_DE_NOMES[[#This Row],[Nome]],'Folha Rainha'!F:F,"AUXILIO TRANSPORTE ") -> 0 | T3: =SUMIFS('Folha Rainha'!G:G,'Folha Rainha'!B:B,BASE_DE_NOMES[[#This Row],[Nome]],'Folha Rainha'!F:F,"ASSISTÊNCIA ODONTOLÓGICA")+SUMIFS('Folha Rainha'!G:G,'Folha Rainha'!B:B,BASE_DE_NOMES[[#This Row],[Nome]],'Folha Rainha'!F:F,"ASSIST. ODONTO OUTROS DEPENDENTES")+SUMIFS('Folha Rainha'!G:G,'Folha Rainha'!B:B,BASE_DE_NOMES[[#This Row],[Nome]],'Folha Rainha'!F:F,"AUXILIO PLANO DE BENEFICIOS DEPENDENTES ") -> 0 | U3: =SUMIFS('Folha Rainha'!G:G,'Folha Rainha'!B:B,BASE_DE_NOMES[[#This Row],[Nome]],'Folha Rainha'!F:F,"BOLSA AUXILIO DESCONTO ADIANTAMENTO")+SUMIFS('Folha Rainha'!G:G,'Folha Rainha'!B:B,BASE_DE_NOMES[[#This Row],[Nome]],'Folha Rainha'!F:F,"DESCONTO PLANO DE SAÚDE")+BASE_DE_NOMES[[#This Row],[TX ASSIS. TOTAL]] -> 0 | V3: =BASE_DE_NOMES[[#This Row],[BOLSA DE AUXILIO]]+BASE_DE_NOMES[[#This Row],[VALE TRANSP]]+BASE_DE_NOMES[[#This Row],[PLANO DE SAUDE]]-BASE_DE_NOMES[[#This Row],[DESCONTOS]] -> 0 | W3: =SUMIFS('Folha Rainha'!G:G,'Folha Rainha'!B:B,BASE_DE_NOMES[[#This Row],[Nome]],'Folha Rainha'!F:F,"VALE COMPRAS")+SUMIFS('Folha Rainha'!G:G,'Folha Rainha'!B:B,BASE_DE_NOMES[[#This Row],[Nome]],'Folha Rainha'!F:F,"VALES") -> 0 | X3: =SUMIFS('Folha Rainha'!G:G,'Folha Rainha'!B:B,BASE_DE_NOMES[[#This Row],[Nome]],'Folha Rainha'!F:F,"ABONO CCT SECOFS 2024-2025")+SUMIFS('Folha Rainha'!G:G,'Folha Rainha'!B:B,BASE_DE_NOMES[[#This Row],[Nome]],'Folha Rainha'!F:F,"PARCELA DIFERENÇA 13o CCT")+SUMIFS('Folha Rainha'!G:G,'Folha Rainha'!B:B,BASE_DE_NOMES[[#This Row],[Nome]],'Folha Rainha'!F:F,"CONTRIBUICAO ABONO CCT 2024-2025") -> 0 | Y3: =BASE_DE_NOMES[[#This Row],[TOTAL DE C.CHEQUE]]+BASE_DE_NOMES[[#This Row],[TOTAL DE QUEBRA]]+BASE_DE_NOMES[[#This Row],[ADC. ANTIGUIDADE]]+BASE_DE_NOMES[[#This Row],[TOTAL DE TRIENIO]]+BASE_DE_NOMES[[#This Row],[CCT]] -> 0 | Z3: =BASE_DE_NOMES[[#This Row],[PAGAMENTOS]]+BASE_DE_NOMES[[#This Row],[GRATIFICAÇÃO]] -> 0 | AA3: =_xlfn.XLOOKUP(BASE_DE_NOMES[[#This Row],[NOME2]],Planilha1!C:C,Planilha1!D:D)*Y3 -> 0 | AB3: =BASE_DE_NOMES[[#This Row],[IMPOSTOS]]+BASE_DE_NOMES[[#This Row],[SALARIO BASE]]+BASE_DE_NOMES[[#This Row],[FAMILIA]] -> 0 | AC3: =_xlfn.XLOOKUP(BASE_DE_NOMES[[#This Row],[Razão Social]],Planilha1!B:B,Planilha1!C:C) -> GENESIS | AD3: =_xlfn.XLOOKUP(BASE_DE_NOMES[[#This Row],[Alocações]],Planilha1!B:B,Planilha1!C:C) -> SR PASSOS
A4: AILTON LUCENA | B4: GERENTE DE VENDAS | C4: GENESIS | D4: GENESIS | E4: =IFERROR(_xlfn.XLOOKUP(BASE_DE_NOMES[[#This Row],[Nome]],'Folha Rainha'!B:B,'Folha Rainha'!D:D),0) -> 39052 | F4: =IFERROR(_xlfn.XLOOKUP(BASE_DE_NOMES[[#This Row],[Nome]],'Folha Rainha'!B:B,'Folha Rainha'!E:E)," ") -> 0 | G4: =SUMIFS('Folha Rainha'!G:G,'Folha Rainha'!B:B,BASE_DE_NOMES[[#This Row],[Nome]],'Folha Rainha'!F:F,"Salário Base")+SUMIFS('Folha Rainha'!G:G,'Folha Rainha'!B:B,BASE_DE_NOMES[[#This Row],[Nome]],'Folha Rainha'!F:F,"Salário:") -> 4296.77 | H4: =SUMIFS('Folha Rainha'!G:G,'Folha Rainha'!B:B,BASE_DE_NOMES[[#This Row],[Nome]],'Folha Rainha'!F:F,"HORAS FALTAS PARCIAL")+SUMIFS('Folha Rainha'!G:G,'Folha Rainha'!B:B,BASE_DE_NOMES[[#This Row],[Nome]],'Folha Rainha'!F:F,"HORAS FALTAS")+SUMIFS('Folha Rainha'!G:G,'Folha Rainha'!B:B,BASE_DE_NOMES[[#This Row],[Nome]],'Folha Rainha'!F:F,"HORAS FALTAS DSR")+SUMIFS('Folha Rainha'!G:G,'Folha Rainha'!B:B,BASE_DE_NOMES[[#This Row],[Nome]],'Folha Rainha'!F:F,"FALTA DE CAIXA") -> 0 | I4: =SUMIFS('Folha Rainha'!G:G,'Folha Rainha'!B:B,BASE_DE_NOMES[[#This Row],[Nome]],'Folha Rainha'!F:F,"DESCONTO HORAS AFASTADAS")+SUMIFS('Folha Rainha'!G:G,'Folha Rainha'!B:B,BASE_DE_NOMES[[#This Row],[Nome]],'Folha Rainha'!F:F,"DESCONTO HORAS AFASTADAS ACID TRABALHO")+SUMIFS('Folha Rainha'!G:G,'Folha Rainha'!B:B,BASE_DE_NOMES[[#This Row],[Nome]],'Folha Rainha'!F:F,"SALARIO MATERNIDADE") -> 0 | J4: =BASE_DE_NOMES[[#This Row],[C.CHEQUE]]-BASE_DE_NOMES[[#This Row],[FALTAS]]-BASE_DE_NOMES[[#This Row],[DESCONTO ]] -> 4296.77 | K4: =SUMIF(GRATIFICAÇÃO!A:A,BASE_DE_NOMES[[#This Row],[Nome]],GRATIFICAÇÃO!F:F) -> 0 | L4: =SUMIF(PG!A:A,BASE_DE_NOMES[[#This Row],[Nome]],PG!E:E) -> 0 | M4: =SUMIFS('Folha Rainha'!G:G,'Folha Rainha'!B:B,BASE_DE_NOMES[[#This Row],[Nome]],'Folha Rainha'!F:F,"*Quebra*",'Folha Rainha'!F:F,"*QUEBRA*") -> 0 | N4: =SUMIFS('Folha Rainha'!G:G,'Folha Rainha'!B:B,BASE_DE_NOMES[[#This Row],[Nome]],'Folha Rainha'!F:F,"ADC. ANTIGUIDADE") -> 0 | O4: =SUMIFS('Folha Rainha'!G:G,'Folha Rainha'!B:B,BASE_DE_NOMES[[#This Row],[Nome]],'Folha Rainha'!F:F,"*Trienio*") -> 644.51 | P4: =SUMIFS('Folha Rainha'!G:G,'Folha Rainha'!B:B,BASE_DE_NOMES[[#This Row],[Nome]],'Folha Rainha'!F:F,"*TAXA*") -> 0 | Q4: =SUMIFS('Folha Rainha'!G:G,'Folha Rainha'!B:B,BASE_DE_NOMES[[#This Row],[Nome]],'Folha Rainha'!F:F,"SALARIO FAMILIA")+SUMIFS('Folha Rainha'!G:G,'Folha Rainha'!B:B,BASE_DE_NOMES[[#This Row],[Nome]],'Folha Rainha'!F:F,"Salário Família") -> 0 | R4: =SUMIFS('Folha Rainha'!G:G,'Folha Rainha'!B:B,BASE_DE_NOMES[[#This Row],[Nome]],'Folha Rainha'!F:F,"BOLSA AUXILIO")+SUMIFS('Folha Rainha'!G:G,'Folha Rainha'!B:B,BASE_DE_NOMES[[#This Row],[Nome]],'Folha Rainha'!F:F,"BOLSA AUXILIO AFASTAMENTO DIREITOS INT") -> 0 | S4: =SUMIFS('Folha Rainha'!G:G,'Folha Rainha'!B:B,BASE_DE_NOMES[[#This Row],[Nome]],'Folha Rainha'!F:F,"Vale Transporte")+SUMIFS('Folha Rainha'!G:G,'Folha Rainha'!B:B,BASE_DE_NOMES[[#This Row],[Nome]],'Folha Rainha'!F:F,"VALE TRANSPORTE 6%")+SUMIFS('Folha Rainha'!G:G,'Folha Rainha'!B:B,BASE_DE_NOMES[[#This Row],[Nome]],'Folha Rainha'!F:F,"AUXILIO TRANSPORTE ") -> 0 | T4: =SUMIFS('Folha Rainha'!G:G,'Folha Rainha'!B:B,BASE_DE_NOMES[[#This Row],[Nome]],'Folha Rainha'!F:F,"ASSISTÊNCIA ODONTOLÓGICA")+SUMIFS('Folha Rainha'!G:G,'Folha Rainha'!B:B,BASE_DE_NOMES[[#This Row],[Nome]],'Folha Rainha'!F:F,"ASSIST. ODONTO OUTROS DEPENDENTES")+SUMIFS('Folha Rainha'!G:G,'Folha Rainha'!B:B,BASE_DE_NOMES[[#This Row],[Nome]],'Folha Rainha'!F:F,"AUXILIO PLANO DE BENEFICIOS DEPENDENTES ") -> 0 | U4: =SUMIFS('Folha Rainha'!G:G,'Folha Rainha'!B:B,BASE_DE_NOMES[[#This Row],[Nome]],'Folha Rainha'!F:F,"BOLSA AUXILIO DESCONTO ADIANTAMENTO")+SUMIFS('Folha Rainha'!G:G,'Folha Rainha'!B:B,BASE_DE_NOMES[[#This Row],[Nome]],'Folha Rainha'!F:F,"DESCONTO PLANO DE SAÚDE")+BASE_DE_NOMES[[#This Row],[TX ASSIS. TOTAL]] -> 0 | V4: =BASE_DE_NOMES[[#This Row],[BOLSA DE AUXILIO]]+BASE_DE_NOMES[[#This Row],[VALE TRANSP]]+BASE_DE_NOMES[[#This Row],[PLANO DE SAUDE]]-BASE_DE_NOMES[[#This Row],[DESCONTOS]] -> 0 | W4: =SUMIFS('Folha Rainha'!G:G,'Folha Rainha'!B:B,BASE_DE_NOMES[[#This Row],[Nome]],'Folha Rainha'!F:F,"VALE COMPRAS")+SUMIFS('Folha Rainha'!G:G,'Folha Rainha'!B:B,BASE_DE_NOMES[[#This Row],[Nome]],'Folha Rainha'!F:F,"VALES") -> 0 | X4: =SUMIFS('Folha Rainha'!G:G,'Folha Rainha'!B:B,BASE_DE_NOMES[[#This Row],[Nome]],'Folha Rainha'!F:F,"ABONO CCT SECOFS 2024-2025")+SUMIFS('Folha Rainha'!G:G,'Folha Rainha'!B:B,BASE_DE_NOMES[[#This Row],[Nome]],'Folha Rainha'!F:F,"PARCELA DIFERENÇA 13o CCT")+SUMIFS('Folha Rainha'!G:G,'Folha Rainha'!B:B,BASE_DE_NOMES[[#This Row],[Nome]],'Folha Rainha'!F:F,"CONTRIBUICAO ABONO CCT 2024-2025") -> 0 | Y4: =BASE_DE_NOMES[[#This Row],[TOTAL DE C.CHEQUE]]+BASE_DE_NOMES[[#This Row],[TOTAL DE QUEBRA]]+BASE_DE_NOMES[[#This Row],[ADC. ANTIGUIDADE]]+BASE_DE_NOMES[[#This Row],[TOTAL DE TRIENIO]]+BASE_DE_NOMES[[#This Row],[CCT]] -> 4941.28 | Z4: =BASE_DE_NOMES[[#This Row],[PAGAMENTOS]]+BASE_DE_NOMES[[#This Row],[GRATIFICAÇÃO]] -> 0 | AA4: =_xlfn.XLOOKUP(BASE_DE_NOMES[[#This Row],[NOME2]],Planilha1!C:C,Planilha1!D:D)*Y4 -> 988.256 | AB4: =BASE_DE_NOMES[[#This Row],[IMPOSTOS]]+BASE_DE_NOMES[[#This Row],[SALARIO BASE]]+BASE_DE_NOMES[[#This Row],[FAMILIA]] -> 5929.536 | AC4: =_xlfn.XLOOKUP(BASE_DE_NOMES[[#This Row],[Razão Social]],Planilha1!B:B,Planilha1!C:C) -> GENESIS | AD4: =_xlfn.XLOOKUP(BASE_DE_NOMES[[#This Row],[Alocações]],Planilha1!B:B,Planilha1!C:C) -> GENESIS
A5: ALBERTO DO NASCIMENTO SANTOS | B5: EMBALADOR (A) | C5: REIS FÁBRICA | D5: REIS FÁBRICA | E5: =IFERROR(_xlfn.XLOOKUP(BASE_DE_NOMES[[#This Row],[Nome]],'Folha Rainha'!B:B,'Folha Rainha'!D:D),0) -> 43222 | F5: =IFERROR(_xlfn.XLOOKUP(BASE_DE_NOMES[[#This Row],[Nome]],'Folha Rainha'!B:B,'Folha Rainha'!E:E)," ") -> Férias | G5: =SUMIFS('Folha Rainha'!G:G,'Folha Rainha'!B:B,BASE_DE_NOMES[[#This Row],[Nome]],'Folha Rainha'!F:F,"Salário Base")+SUMIFS('Folha Rainha'!G:G,'Folha Rainha'!B:B,BASE_DE_NOMES[[#This Row],[Nome]],'Folha Rainha'!F:F,"Salário:") -> 1518 | H5: =SUMIFS('Folha Rainha'!G:G,'Folha Rainha'!B:B,BASE_DE_NOMES[[#This Row],[Nome]],'Folha Rainha'!F:F,"HORAS FALTAS PARCIAL")+SUMIFS('Folha Rainha'!G:G,'Folha Rainha'!B:B,BASE_DE_NOMES[[#This Row],[Nome]],'Folha Rainha'!F:F,"HORAS FALTAS")+SUMIFS('Folha Rainha'!G:G,'Folha Rainha'!B:B,BASE_DE_NOMES[[#This Row],[Nome]],'Folha Rainha'!F:F,"HORAS FALTAS DSR")+SUMIFS('Folha Rainha'!G:G,'Folha Rainha'!B:B,BASE_DE_NOMES[[#This Row],[Nome]],'Folha Rainha'!F:F,"FALTA DE CAIXA") -> 0 | I5: =SUMIFS('Folha Rainha'!G:G,'Folha Rainha'!B:B,BASE_DE_NOMES[[#This Row],[Nome]],'Folha Rainha'!F:F,"DESCONTO HORAS AFASTADAS")+SUMIFS('Folha Rainha'!G:G,'Folha Rainha'!B:B,BASE_DE_NOMES[[#This Row],[Nome]],'Folha Rainha'!F:F,"DESCONTO HORAS AFASTADAS ACID TRABALHO")+SUMIFS('Folha Rainha'!G:G,'Folha Rainha'!B:B,BASE_DE_NOMES[[#This Row],[Nome]],'Folha Rainha'!F:F,"SALARIO MATERNIDADE") -> 0 | J5: =BASE_DE_NOMES[[#This Row],[C.CHEQUE]]-BASE_DE_NOMES[[#This Row],[FALTAS]]-BASE_DE_NOMES[[#This Row],[DESCONTO ]] -> 1518 | K5: =SUMIF(GRATIFICAÇÃO!A:A,BASE_DE_NOMES[[#This Row],[Nome]],GRATIFICAÇÃO!F:F) -> 100 | L5: =SUMIF(PG!A:A,BASE_DE_NOMES[[#This Row],[Nome]],PG!E:E) -> 0 | M5: =SUMIFS('Folha Rainha'!G:G,'Folha Rainha'!B:B,BASE_DE_NOMES[[#This Row],[Nome]],'Folha Rainha'!F:F,"*Quebra*",'Folha Rainha'!F:F,"*QUEBRA*") -> 0 | N5: =SUMIFS('Folha Rainha'!G:G,'Folha Rainha'!B:B,BASE_DE_NOMES[[#This Row],[Nome]],'Folha Rainha'!F:F,"ADC. ANTIGUIDADE") -> 0 | O5: =SUMIFS('Folha Rainha'!G:G,'Folha Rainha'!B:B,BASE_DE_NOMES[[#This Row],[Nome]],'Folha Rainha'!F:F,"*Trienio*") -> 0 | P5: =SUMIFS('Folha Rainha'!G:G,'Folha Rainha'!B:B,BASE_DE_NOMES[[#This Row],[Nome]],'Folha Rainha'!F:F,"*TAXA*") -> 0 | Q5: =SUMIFS('Folha Rainha'!G:G,'Folha Rainha'!B:B,BASE_DE_NOMES[[#This Row],[Nome]],'Folha Rainha'!F:F,"SALARIO FAMILIA")+SUMIFS('Folha Rainha'!G:G,'Folha Rainha'!B:B,BASE_DE_NOMES[[#This Row],[Nome]],'Folha Rainha'!F:F,"Salário Família") -> 0 | R5: =SUMIFS('Folha Rainha'!G:G,'Folha Rainha'!B:B,BASE_DE_NOMES[[#This Row],[Nome]],'Folha Rainha'!F:F,"BOLSA AUXILIO")+SUMIFS('Folha Rainha'!G:G,'Folha Rainha'!B:B,BASE_DE_NOMES[[#This Row],[Nome]],'Folha Rainha'!F:F,"BOLSA AUXILIO AFASTAMENTO DIREITOS INT") -> 0 | S5: =SUMIFS('Folha Rainha'!G:G,'Folha Rainha'!B:B,BASE_DE_NOMES[[#This Row],[Nome]],'Folha Rainha'!F:F,"Vale Transporte")+SUMIFS('Folha Rainha'!G:G,'Folha Rainha'!B:B,BASE_DE_NOMES[[#This Row],[Nome]],'Folha Rainha'!F:F,"VALE TRANSPORTE 6%")+SUMIFS('Folha Rainha'!G:G,'Folha Rainha'!B:B,BASE_DE_NOMES[[#This Row],[Nome]],'Folha Rainha'!F:F,"AUXILIO TRANSPORTE ") -> 0 | T5: =SUMIFS('Folha Rainha'!G:G,'Folha Rainha'!B:B,BASE_DE_NOMES[[#This Row],[Nome]],'Folha Rainha'!F:F,"ASSISTÊNCIA ODONTOLÓGICA")+SUMIFS('Folha Rainha'!G:G,'Folha Rainha'!B:B,BASE_DE_NOMES[[#This Row],[Nome]],'Folha Rainha'!F:F,"ASSIST. ODONTO OUTROS DEPENDENTES")+SUMIFS('Folha Rainha'!G:G,'Folha Rainha'!B:B,BASE_DE_NOMES[[#This Row],[Nome]],'Folha Rainha'!F:F,"AUXILIO PLANO DE BENEFICIOS DEPENDENTES ") -> 0 | U5: =SUMIFS('Folha Rainha'!G:G,'Folha Rainha'!B:B,BASE_DE_NOMES[[#This Row],[Nome]],'Folha Rainha'!F:F,"BOLSA AUXILIO DESCONTO ADIANTAMENTO")+SUMIFS('Folha Rainha'!G:G,'Folha Rainha'!B:B,BASE_DE_NOMES[[#This Row],[Nome]],'Folha Rainha'!F:F,"DESCONTO PLANO DE SAÚDE")+BASE_DE_NOMES[[#This Row],[TX ASSIS. TOTAL]] -> 0 | V5: =BASE_DE_NOMES[[#This Row],[BOLSA DE AUXILIO]]+BASE_DE_NOMES[[#This Row],[VALE TRANSP]]+BASE_DE_NOMES[[#This Row],[PLANO DE SAUDE]]-BASE_DE_NOMES[[#This Row],[DESCONTOS]] -> 0 | W5: =SUMIFS('Folha Rainha'!G:G,'Folha Rainha'!B:B,BASE_DE_NOMES[[#This Row],[Nome]],'Folha Rainha'!F:F,"VALE COMPRAS")+SUMIFS('Folha Rainha'!G:G,'Folha Rainha'!B:B,BASE_DE_NOMES[[#This Row],[Nome]],'Folha Rainha'!F:F,"VALES") -> 0 | X5: =SUMIFS('Folha Rainha'!G:G,'Folha Rainha'!B:B,BASE_DE_NOMES[[#This Row],[Nome]],'Folha Rainha'!F:F,"ABONO CCT SECOFS 2024-2025")+SUMIFS('Folha Rainha'!G:G,'Folha Rainha'!B:B,BASE_DE_NOMES[[#This Row],[Nome]],'Folha Rainha'!F:F,"PARCELA DIFERENÇA 13o CCT")+SUMIFS('Folha Rainha'!G:G,'Folha Rainha'!B:B,BASE_DE_NOMES[[#This Row],[Nome]],'Folha Rainha'!F:F,"CONTRIBUICAO ABONO CCT 2024-2025") -> 0 | Y5: =BASE_DE_NOMES[[#This Row],[TOTAL DE C.CHEQUE]]+BASE_DE_NOMES[[#This Row],[TOTAL DE QUEBRA]]+BASE_DE_NOMES[[#This Row],[ADC. ANTIGUIDADE]]+BASE_DE_NOMES[[#This Row],[TOTAL DE TRIENIO]]+BASE_DE_NOMES[[#This Row],[CCT]] -> 1518 | Z5: =BASE_DE_NOMES[[#This Row],[PAGAMENTOS]]+BASE_DE_NOMES[[#This Row],[GRATIFICAÇÃO]] -> 100 | AA5: =_xlfn.XLOOKUP(BASE_DE_NOMES[[#This Row],[NOME2]],Planilha1!C:C,Planilha1!D:D)*Y5 -> 764.0094 | AB5: =BASE_DE_NOMES[[#This Row],[IMPOSTOS]]+BASE_DE_NOMES[[#This Row],[SALARIO BASE]]+BASE_DE_NOMES[[#This Row],[FAMILIA]] -> 2282.0094 | AC5: =_xlfn.XLOOKUP(BASE_DE_NOMES[[#This Row],[Razão Social]],Planilha1!B:B,Planilha1!C:C) -> FABRICA | AD5: =_xlfn.XLOOKUP(BASE_DE_NOMES[[#This Row],[Alocações]],Planilha1!B:B,Planilha1!C:C) -> FABRICA
A6: ALDA COITINHO DA SILVA | B6: VENDEDOR | C6: 05K | D6: GENESIS | E6: =IFERROR(_xlfn.XLOOKUP(BASE_DE_NOMES[[#This Row],[Nome]],'Folha Rainha'!B:B,'Folha Rainha'!D:D),0) -> 0 | F6: =IFERROR(_xlfn.XLOOKUP(BASE_DE_NOMES[[#This Row],[Nome]],'Folha Rainha'!B:B,'Folha Rainha'!E:E)," ") | G6: =SUMIFS('Folha Rainha'!G:G,'Folha Rainha'!B:B,BASE_DE_NOMES[[#This Row],[Nome]],'Folha Rainha'!F:F,"Salário Base")+SUMIFS('Folha Rainha'!G:G,'Folha Rainha'!B:B,BASE_DE_NOMES[[#This Row],[Nome]],'Folha Rainha'!F:F,"Salário:") -> 0 | H6: =SUMIFS('Folha Rainha'!G:G,'Folha Rainha'!B:B,BASE_DE_NOMES[[#This Row],[Nome]],'Folha Rainha'!F:F,"HORAS FALTAS PARCIAL")+SUMIFS('Folha Rainha'!G:G,'Folha Rainha'!B:B,BASE_DE_NOMES[[#This Row],[Nome]],'Folha Rainha'!F:F,"HORAS FALTAS")+SUMIFS('Folha Rainha'!G:G,'Folha Rainha'!B:B,BASE_DE_NOMES[[#This Row],[Nome]],'Folha Rainha'!F:F,"HORAS FALTAS DSR")+SUMIFS('Folha Rainha'!G:G,'Folha Rainha'!B:B,BASE_DE_NOMES[[#This Row],[Nome]],'Folha Rainha'!F:F,"FALTA DE CAIXA") -> 0 | I6: =SUMIFS('Folha Rainha'!G:G,'Folha Rainha'!B:B,BASE_DE_NOMES[[#This Row],[Nome]],'Folha Rainha'!F:F,"DESCONTO HORAS AFASTADAS")+SUMIFS('Folha Rainha'!G:G,'Folha Rainha'!B:B,BASE_DE_NOMES[[#This Row],[Nome]],'Folha Rainha'!F:F,"DESCONTO HORAS AFASTADAS ACID TRABALHO")+SUMIFS('Folha Rainha'!G:G,'Folha Rainha'!B:B,BASE_DE_NOMES[[#This Row],[Nome]],'Folha Rainha'!F:F,"SALARIO MATERNIDADE") -> 0 | J6: =BASE_DE_NOMES[[#This Row],[C.CHEQUE]]-BASE_DE_NOMES[[#This Row],[FALTAS]]-BASE_DE_NOMES[[#This Row],[DESCONTO ]] -> 0 | K6: =SUMIF(GRATIFICAÇÃO!A:A,BASE_DE_NOMES[[#This Row],[Nome]],GRATIFICAÇÃO!F:F) -> 0 | L6: =SUMIF(PG!A:A,BASE_DE_NOMES[[#This Row],[Nome]],PG!E:E) -> 0 | M6: =SUMIFS('Folha Rainha'!G:G,'Folha Rainha'!B:B,BASE_DE_NOMES[[#This Row],[Nome]],'Folha Rainha'!F:F,"*Quebra*",'Folha Rainha'!F:F,"*QUEBRA*") -> 0 | N6: =SUMIFS('Folha Rainha'!G:G,'Folha Rainha'!B:B,BASE_DE_NOMES[[#This Row],[Nome]],'Folha Rainha'!F:F,"ADC. ANTIGUIDADE") -> 0 | O6: =SUMIFS('Folha Rainha'!G:G,'Folha Rainha'!B:B,BASE_DE_NOMES[[#This Row],[Nome]],'Folha Rainha'!F:F,"*Trienio*") -> 0 | P6: =SUMIFS('Folha Rainha'!G:G,'Folha Rainha'!B:B,BASE_DE_NOMES[[#This Row],[Nome]],'Folha Rainha'!F:F,"*TAXA*") -> 0 | Q6: =SUMIFS('Folha Rainha'!G:G,'Folha Rainha'!B:B,BASE_DE_NOMES[[#This Row],[Nome]],'Folha Rainha'!F:F,"SALARIO FAMILIA")+SUMIFS('Folha Rainha'!G:G,'Folha Rainha'!B:B,BASE_DE_NOMES[[#This Row],[Nome]],'Folha Rainha'!F:F,"Salário Família") -> 0 | R6: =SUMIFS('Folha Rainha'!G:G,'Folha Rainha'!B:B,BASE_DE_NOMES[[#This Row],[Nome]],'Folha Rainha'!F:F,"BOLSA AUXILIO")+SUMIFS('Folha Rainha'!G:G,'Folha Rainha'!B:B,BASE_DE_NOMES[[#This Row],[Nome]],'Folha Rainha'!F:F,"BOLSA AUXILIO AFASTAMENTO DIREITOS INT") -> 0 | S6: =SUMIFS('Folha Rainha'!G:G,'Folha Rainha'!B:B,BASE_DE_NOMES[[#This Row],[Nome]],'Folha Rainha'!F:F,"Vale Transporte")+SUMIFS('Folha Rainha'!G:G,'Folha Rainha'!B:B,BASE_DE_NOMES[[#This Row],[Nome]],'Folha Rainha'!F:F,"VALE TRANSPORTE 6%")+SUMIFS('Folha Rainha'!G:G,'Folha Rainha'!B:B,BASE_DE_NOMES[[#This Row],[Nome]],'Folha Rainha'!F:F,"AUXILIO TRANSPORTE ") -> 0 | T6: =SUMIFS('Folha Rainha'!G:G,'Folha Rainha'!B:B,BASE_DE_NOMES[[#This Row],[Nome]],'Folha Rainha'!F:F,"ASSISTÊNCIA ODONTOLÓGICA")+SUMIFS('Folha Rainha'!G:G,'Folha Rainha'!B:B,BASE_DE_NOMES[[#This Row],[Nome]],'Folha Rainha'!F:F,"ASSIST. ODONTO OUTROS DEPENDENTES")+SUMIFS('Folha Rainha'!G:G,'Folha Rainha'!B:B,BASE_DE_NOMES[[#This Row],[Nome]],'Folha Rainha'!F:F,"AUXILIO PLANO DE BENEFICIOS DEPENDENTES ") -> 0 | U6: =SUMIFS('Folha Rainha'!G:G,'Folha Rainha'!B:B,BASE_DE_NOMES[[#This Row],[Nome]],'Folha Rainha'!F:F,"BOLSA AUXILIO DESCONTO ADIANTAMENTO")+SUMIFS('Folha Rainha'!G:G,'Folha Rainha'!B:B,BASE_DE_NOMES[[#This Row],[Nome]],'Folha Rainha'!F:F,"DESCONTO PLANO DE SAÚDE")+BASE_DE_NOMES[[#This Row],[TX ASSIS. TOTAL]] -> 0 | V6: =BASE_DE_NOMES[[#This Row],[BOLSA DE AUXILIO]]+BASE_DE_NOMES[[#This Row],[VALE TRANSP]]+BASE_DE_NOMES[[#This Row],[PLANO DE SAUDE]]-BASE_DE_NOMES[[#This Row],[DESCONTOS]] -> 0 | W6: =SUMIFS('Folha Rainha'!G:G,'Folha Rainha'!B:B,BASE_DE_NOMES[[#This Row],[Nome]],'Folha Rainha'!F:F,"VALE COMPRAS")+SUMIFS('Folha Rainha'!G:G,'Folha Rainha'!B:B,BASE_DE_NOMES[[#This Row],[Nome]],'Folha Rainha'!F:F,"VALES") -> 0 | X6: =SUMIFS('Folha Rainha'!G:G,'Folha Rainha'!B:B,BASE_DE_NOMES[[#This Row],[Nome]],'Folha Rainha'!F:F,"ABONO CCT SECOFS 2024-2025")+SUMIFS('Folha Rainha'!G:G,'Folha Rainha'!B:B,BASE_DE_NOMES[[#This Row],[Nome]],'Folha Rainha'!F:F,"PARCELA DIFERENÇA 13o CCT")+SUMIFS('Folha Rainha'!G:G,'Folha Rainha'!B:B,BASE_DE_NOMES[[#This Row],[Nome]],'Folha Rainha'!F:F,"CONTRIBUICAO ABONO CCT 2024-2025") -> 0 | Y6: =BASE_DE_NOMES[[#This Row],[TOTAL DE C.CHEQUE]]+BASE_DE_NOMES[[#This Row],[TOTAL DE QUEBRA]]+BASE_DE_NOMES[[#This Row],[ADC. ANTIGUIDADE]]+BASE_DE_NOMES[[#This Row],[TOTAL DE TRIENIO]]+BASE_DE_NOMES[[#This Row],[CCT]] -> 0 | Z6: =BASE_DE_NOMES[[#This Row],[PAGAMENTOS]]+BASE_DE_NOMES[[#This Row],[GRATIFICAÇÃO]] -> 0 | AA6: =_xlfn.XLOOKUP(BASE_DE_NOMES[[#This Row],[NOME2]],Planilha1!C:C,Planilha1!D:D)*Y6 -> 0 | AB6: =BASE_DE_NOMES[[#This Row],[IMPOSTOS]]+BASE_DE_NOMES[[#This Row],[SALARIO BASE]]+BASE_DE_NOMES[[#This Row],[FAMILIA]] -> 0 | AC6: =_xlfn.XLOOKUP(BASE_DE_NOMES[[#This Row],[Razão Social]],Planilha1!B:B,Planilha1!C:C) -> 5K DECORAÇÕES | AD6: =_xlfn.XLOOKUP(BASE_DE_NOMES[[#This Row],[Alocações]],Planilha1!B:B,Planilha1!C:C) -> GENESIS
A7: ALESSANDRO BATISTA DA ROCHA | B7: EMBALADOR (A) | C7: REIS FÁBRICA | D7: REIS FÁBRICA | E7: =IFERROR(_xlfn.XLOOKUP(BASE_DE_NOMES[[#This Row],[Nome]],'Folha Rainha'!B:B,'Folha Rainha'!D:D),0) -> 44637 | F7: =IFERROR(_xlfn.XLOOKUP(BASE_DE_NOMES[[#This Row],[Nome]],'Folha Rainha'!B:B,'Folha Rainha'!E:E)," ") -> Trabalhando | G7: =SUMIFS('Folha Rainha'!G:G,'Folha Rainha'!B:B,BASE_DE_NOMES[[#This Row],[Nome]],'Folha Rainha'!F:F,"Salário Base")+SUMIFS('Folha Rainha'!G:G,'Folha Rainha'!B:B,BASE_DE_NOMES[[#This Row],[Nome]],'Folha Rainha'!F:F,"Salário:") -> 1518 | H7: =SUMIFS('Folha Rainha'!G:G,'Folha Rainha'!B:B,BASE_DE_NOMES[[#This Row],[Nome]],'Folha Rainha'!F:F,"HORAS FALTAS PARCIAL")+SUMIFS('Folha Rainha'!G:G,'Folha Rainha'!B:B,BASE_DE_NOMES[[#This Row],[Nome]],'Folha Rainha'!F:F,"HORAS FALTAS")+SUMIFS('Folha Rainha'!G:G,'Folha Rainha'!B:B,BASE_DE_NOMES[[#This Row],[Nome]],'Folha Rainha'!F:F,"HORAS FALTAS DSR")+SUMIFS('Folha Rainha'!G:G,'Folha Rainha'!B:B,BASE_DE_NOMES[[#This Row],[Nome]],'Folha Rainha'!F:F,"FALTA DE CAIXA") -> 0 | I7: =SUMIFS('Folha Rainha'!G:G,'Folha Rainha'!B:B,BASE_DE_NOMES[[#This Row],[Nome]],'Folha Rainha'!F:F,"DESCONTO HORAS AFASTADAS")+SUMIFS('Folha Rainha'!G:G,'Folha Rainha'!B:B,BASE_DE_NOMES[[#This Row],[Nome]],'Folha Rainha'!F:F,"DESCONTO HORAS AFASTADAS ACID TRABALHO")+SUMIFS('Folha Rainha'!G:G,'Folha Rainha'!B:B,BASE_DE_NOMES[[#This Row],[Nome]],'Folha Rainha'!F:F,"SALARIO MATERNIDADE") -> 0 | J7: =BASE_DE_NOMES[[#This Row],[C.CHEQUE]]-BASE_DE_NOMES[[#This Row],[FALTAS]]-BASE_DE_NOMES[[#This Row],[DESCONTO ]] -> 1518 | K7: =SUMIF(GRATIFICAÇÃO!A:A,BASE_DE_NOMES[[#This Row],[Nome]],GRATIFICAÇÃO!F:F) -> 200 | L7: =SUMIF(PG!A:A,BASE_DE_NOMES[[#This Row],[Nome]],PG!E:E) -> 0 | M7: =SUMIFS('Folha Rainha'!G:G,'Folha Rainha'!B:B,BASE_DE_NOMES[[#This Row],[Nome]],'Folha Rainha'!F:F,"*Quebra*",'Folha Rainha'!F:F,"*QUEBRA*") -> 0 | N7: =SUMIFS('Folha Rainha'!G:G,'Folha Rainha'!B:B,BASE_DE_NOMES[[#This Row],[Nome]],'Folha Rainha'!F:F,"ADC. ANTIGUIDADE") -> 0 | O7: =SUMIFS('Folha Rainha'!G:G,'Folha Rainha'!B:B,BASE_DE_NOMES[[#This Row],[Nome]],'Folha Rainha'!F:F,"*Trienio*") -> 0 | P7: =SUMIFS('Folha Rainha'!G:G,'Folha Rainha'!B:B,BASE_DE_NOMES[[#This Row],[Nome]],'Folha Rainha'!F:F,"*TAXA*") -> 0 | Q7: =SUMIFS('Folha Rainha'!G:G,'Folha Rainha'!B:B,BASE_DE_NOMES[[#This Row],[Nome]],'Folha Rainha'!F:F,"SALARIO FAMILIA")+SUMIFS('Folha Rainha'!G:G,'Folha Rainha'!B:B,BASE_DE_NOMES[[#This Row],[Nome]],'Folha Rainha'!F:F,"Salário Família") -> 0 | R7: =SUMIFS('Folha Rainha'!G:G,'Folha Rainha'!B:B,BASE_DE_NOMES[[#This Row],[Nome]],'Folha Rainha'!F:F,"BOLSA AUXILIO")+SUMIFS('Folha Rainha'!G:G,'Folha Rainha'!B:B,BASE_DE_NOMES[[#This Row],[Nome]],'Folha Rainha'!F:F,"BOLSA AUXILIO AFASTAMENTO DIREITOS INT") -> 0 | S7: =SUMIFS('Folha Rainha'!G:G,'Folha Rainha'!B:B,BASE_DE_NOMES[[#This Row],[Nome]],'Folha Rainha'!F:F,"Vale Transporte")+SUMIFS('Folha Rainha'!G:G,'Folha Rainha'!B:B,BASE_DE_NOMES[[#This Row],[Nome]],'Folha Rainha'!F:F,"VALE TRANSPORTE 6%")+SUMIFS('Folha Rainha'!G:G,'Folha Rainha'!B:B,BASE_DE_NOMES[[#This Row],[Nome]],'Folha Rainha'!F:F,"AUXILIO TRANSPORTE ") -> 0 | T7: =SUMIFS('Folha Rainha'!G:G,'Folha Rainha'!B:B,BASE_DE_NOMES[[#This Row],[Nome]],'Folha Rainha'!F:F,"ASSISTÊNCIA ODONTOLÓGICA")+SUMIFS('Folha Rainha'!G:G,'Folha Rainha'!B:B,BASE_DE_NOMES[[#This Row],[Nome]],'Folha Rainha'!F:F,"ASSIST. ODONTO OUTROS DEPENDENTES")+SUMIFS('Folha Rainha'!G:G,'Folha Rainha'!B:B,BASE_DE_NOMES[[#This Row],[Nome]],'Folha Rainha'!F:F,"AUXILIO PLANO DE BENEFICIOS DEPENDENTES ") -> 0 | U7: =SUMIFS('Folha Rainha'!G:G,'Folha Rainha'!B:B,BASE_DE_NOMES[[#This Row],[Nome]],'Folha Rainha'!F:F,"BOLSA AUXILIO DESCONTO ADIANTAMENTO")+SUMIFS('Folha Rainha'!G:G,'Folha Rainha'!B:B,BASE_DE_NOMES[[#This Row],[Nome]],'Folha Rainha'!F:F,"DESCONTO PLANO DE SAÚDE")+BASE_DE_NOMES[[#This Row],[TX ASSIS. TOTAL]] -> 0 | V7: =BASE_DE_NOMES[[#This Row],[BOLSA DE AUXILIO]]+BASE_DE_NOMES[[#This Row],[VALE TRANSP]]+BASE_DE_NOMES[[#This Row],[PLANO DE SAUDE]]-BASE_DE_NOMES[[#This Row],[DESCONTOS]] -> 0 | W7: =SUMIFS('Folha Rainha'!G:G,'Folha Rainha'!B:B,BASE_DE_NOMES[[#This Row],[Nome]],'Folha Rainha'!F:F,"VALE COMPRAS")+SUMIFS('Folha Rainha'!G:G,'Folha Rainha'!B:B,BASE_DE_NOMES[[#This Row],[Nome]],'Folha Rainha'!F:F,"VALES") -> 0 | X7: =SUMIFS('Folha Rainha'!G:G,'Folha Rainha'!B:B,BASE_DE_NOMES[[#This Row],[Nome]],'Folha Rainha'!F:F,"ABONO CCT SECOFS 2024-2025")+SUMIFS('Folha Rainha'!G:G,'Folha Rainha'!B:B,BASE_DE_NOMES[[#This Row],[Nome]],'Folha Rainha'!F:F,"PARCELA DIFERENÇA 13o CCT")+SUMIFS('Folha Rainha'!G:G,'Folha Rainha'!B:B,BASE_DE_NOMES[[#This Row],[Nome]],'Folha Rainha'!F:F,"CONTRIBUICAO ABONO CCT 2024-2025") -> 0 | Y7: =BASE_DE_NOMES[[#This Row],[TOTAL DE C.CHEQUE]]+BASE_DE_NOMES[[#This Row],[TOTAL DE QUEBRA]]+BASE_DE_NOMES[[#This Row],[ADC. ANTIGUIDADE]]+BASE_DE_NOMES[[#This Row],[TOTAL DE TRIENIO]]+BASE_DE_NOMES[[#This Row],[CCT]] -> 1518 | Z7: =BASE_DE_NOMES[[#This Row],[PAGAMENTOS]]+BASE_DE_NOMES[[#This Row],[GRATIFICAÇÃO]] -> 200 | AA7: =_xlfn.XLOOKUP(BASE_DE_NOMES[[#This Row],[NOME2]],Planilha1!C:C,Planilha1!D:D)*Y7 -> 764.0094 | AB7: =BASE_DE_NOMES[[#This Row],[IMPOSTOS]]+BASE_DE_NOMES[[#This Row],[SALARIO BASE]]+BASE_DE_NOMES[[#This Row],[FAMILIA]] -> 2282.0094 | AC7: =_xlfn.XLOOKUP(BASE_DE_NOMES[[#This Row],[Razão Social]],Planilha1!B:B,Planilha1!C:C) -> FABRICA | AD7: =_xlfn.XLOOKUP(BASE_DE_NOMES[[#This Row],[Alocações]],Planilha1!B:B,Planilha1!C:C) -> FABRICA
A8: ALINE DE SOUZA SANTOS | B8: VENDEDOR | C8: 30K | D8: 30K | E8: =IFERROR(_xlfn.XLOOKUP(BASE_DE_NOMES[[#This Row],[Nome]],'Folha Rainha'!B:B,'Folha Rainha'!D:D),0) -> 45056 | F8: =IFERROR(_xlfn.XLOOKUP(BASE_DE_NOMES[[#This Row],[Nome]],'Folha Rainha'!B:B,'Folha Rainha'!E:E)," ") -> Trabalhando | G8: =SUMIFS('Folha Rainha'!G:G,'Folha Rainha'!B:B,BASE_DE_NOMES[[#This Row],[Nome]],'Folha Rainha'!F:F,"Salário Base")+SUMIFS('Folha Rainha'!G:G,'Folha Rainha'!B:B,BASE_DE_NOMES[[#This Row],[Nome]],'Folha Rainha'!F:F,"Salário:") -> 1607 | H8: =SUMIFS('Folha Rainha'!G:G,'Folha Rainha'!B:B,BASE_DE_NOMES[[#This Row],[Nome]],'Folha Rainha'!F:F,"HORAS FALTAS PARCIAL")+SUMIFS('Folha Rainha'!G:G,'Folha Rainha'!B:B,BASE_DE_NOMES[[#This Row],[Nome]],'Folha Rainha'!F:F,"HORAS FALTAS")+SUMIFS('Folha Rainha'!G:G,'Folha Rainha'!B:B,BASE_DE_NOMES[[#This Row],[Nome]],'Folha Rainha'!F:F,"HORAS FALTAS DSR")+SUMIFS('Folha Rainha'!G:G,'Folha Rainha'!B:B,BASE_DE_NOMES[[#This Row],[Nome]],'Folha Rainha'!F:F,"FALTA DE CAIXA") -> 0 | I8: =SUMIFS('Folha Rainha'!G:G,'Folha Rainha'!B:B,BASE_DE_NOMES[[#This Row],[Nome]],'Folha Rainha'!F:F,"DESCONTO HORAS AFASTADAS")+SUMIFS('Folha Rainha'!G:G,'Folha Rainha'!B:B,BASE_DE_NOMES[[#This Row],[Nome]],'Folha Rainha'!F:F,"DESCONTO HORAS AFASTADAS ACID TRABALHO")+SUMIFS('Folha Rainha'!G:G,'Folha Rainha'!B:B,BASE_DE_NOMES[[#This Row],[Nome]],'Folha Rainha'!F:F,"SALARIO MATERNIDADE") -> 0 | J8: =BASE_DE_NOMES[[#This Row],[C.CHEQUE]]-BASE_DE_NOMES[[#This Row],[FALTAS]]-BASE_DE_NOMES[[#This Row],[DESCONTO ]] -> 1607 | K8: =SUMIF(GRATIFICAÇÃO!A:A,BASE_DE_NOMES[[#This Row],[Nome]],GRATIFICAÇÃO!F:F) -> 0 | L8: =SUMIF(PG!A:A,BASE_DE_NOMES[[#This Row],[Nome]],PG!E:E) -> 0 | M8: =SUMIFS('Folha Rainha'!G:G,'Folha Rainha'!B:B,BASE_DE_NOMES[[#This Row],[Nome]],'Folha Rainha'!F:F,"*Quebra*",'Folha Rainha'!F:F,"*QUEBRA*") -> 0 | N8: =SUMIFS('Folha Rainha'!G:G,'Folha Rainha'!B:B,BASE_DE_NOMES[[#This Row],[Nome]],'Folha Rainha'!F:F,"ADC. ANTIGUIDADE") -> 0 | O8: =SUMIFS('Folha Rainha'!G:G,'Folha Rainha'!B:B,BASE_DE_NOMES[[#This Row],[Nome]],'Folha Rainha'!F:F,"*Trienio*") -> 0 | P8: =SUMIFS('Folha Rainha'!G:G,'Folha Rainha'!B:B,BASE_DE_NOMES[[#This Row],[Nome]],'Folha Rainha'!F:F,"*TAXA*") -> 0 | Q8: =SUMIFS('Folha Rainha'!G:G,'Folha Rainha'!B:B,BASE_DE_NOMES[[#This Row],[Nome]],'Folha Rainha'!F:F,"SALARIO FAMILIA")+SUMIFS('Folha Rainha'!G:G,'Folha Rainha'!B:B,BASE_DE_NOMES[[#This Row],[Nome]],'Folha Rainha'!F:F,"Salário Família") -> 0 | R8: =SUMIFS('Folha Rainha'!G:G,'Folha Rainha'!B:B,BASE_DE_NOMES[[#This Row],[Nome]],'Folha Rainha'!F:F,"BOLSA AUXILIO")+SUMIFS('Folha Rainha'!G:G,'Folha Rainha'!B:B,BASE_DE_NOMES[[#This Row],[Nome]],'Folha Rainha'!F:F,"BOLSA AUXILIO AFASTAMENTO DIREITOS INT") -> 0 | S8: =SUMIFS('Folha Rainha'!G:G,'Folha Rainha'!B:B,BASE_DE_NOMES[[#This Row],[Nome]],'Folha Rainha'!F:F,"Vale Transporte")+SUMIFS('Folha Rainha'!G:G,'Folha Rainha'!B:B,BASE_DE_NOMES[[#This Row],[Nome]],'Folha Rainha'!F:F,"VALE TRANSPORTE 6%")+SUMIFS('Folha Rainha'!G:G,'Folha Rainha'!B:B,BASE_DE_NOMES[[#This Row],[Nome]],'Folha Rainha'!F:F,"AUXILIO TRANSPORTE ") -> 0 | T8: =SUMIFS('Folha Rainha'!G:G,'Folha Rainha'!B:B,BASE_DE_NOMES[[#This Row],[Nome]],'Folha Rainha'!F:F,"ASSISTÊNCIA ODONTOLÓGICA")+SUMIFS('Folha Rainha'!G:G,'Folha Rainha'!B:B,BASE_DE_NOMES[[#This Row],[Nome]],'Folha Rainha'!F:F,"ASSIST. ODONTO OUTROS DEPENDENTES")+SUMIFS('Folha Rainha'!G:G,'Folha Rainha'!B:B,BASE_DE_NOMES[[#This Row],[Nome]],'Folha Rainha'!F:F,"AUXILIO PLANO DE BENEFICIOS DEPENDENTES ") -> 0 | U8: =SUMIFS('Folha Rainha'!G:G,'Folha Rainha'!B:B,BASE_DE_NOMES[[#This Row],[Nome]],'Folha Rainha'!F:F,"BOLSA AUXILIO DESCONTO ADIANTAMENTO")+SUMIFS('Folha Rainha'!G:G,'Folha Rainha'!B:B,BASE_DE_NOMES[[#This Row],[Nome]],'Folha Rainha'!F:F,"DESCONTO PLANO DE SAÚDE")+BASE_DE_NOMES[[#This Row],[TX ASSIS. TOTAL]] -> 0 | V8: =BASE_DE_NOMES[[#This Row],[BOLSA DE AUXILIO]]+BASE_DE_NOMES[[#This Row],[VALE TRANSP]]+BASE_DE_NOMES[[#This Row],[PLANO DE SAUDE]]-BASE_DE_NOMES[[#This Row],[DESCONTOS]] -> 0 | W8: =SUMIFS('Folha Rainha'!G:G,'Folha Rainha'!B:B,BASE_DE_NOMES[[#This Row],[Nome]],'Folha Rainha'!F:F,"VALE COMPRAS")+SUMIFS('Folha Rainha'!G:G,'Folha Rainha'!B:B,BASE_DE_NOMES[[#This Row],[Nome]],'Folha Rainha'!F:F,"VALES") -> 132.65 | X8: =SUMIFS('Folha Rainha'!G:G,'Folha Rainha'!B:B,BASE_DE_NOMES[[#This Row],[Nome]],'Folha Rainha'!F:F,"ABONO CCT SECOFS 2024-2025")+SUMIFS('Folha Rainha'!G:G,'Folha Rainha'!B:B,BASE_DE_NOMES[[#This Row],[Nome]],'Folha Rainha'!F:F,"PARCELA DIFERENÇA 13o CCT")+SUMIFS('Folha Rainha'!G:G,'Folha Rainha'!B:B,BASE_DE_NOMES[[#This Row],[Nome]],'Folha Rainha'!F:F,"CONTRIBUICAO ABONO CCT 2024-2025") -> 0 | Y8: =BASE_DE_NOMES[[#This Row],[TOTAL DE C.CHEQUE]]+BASE_DE_NOMES[[#This Row],[TOTAL DE QUEBRA]]+BASE_DE_NOMES[[#This Row],[ADC. ANTIGUIDADE]]+BASE_DE_NOMES[[#This Row],[TOTAL DE TRIENIO]]+BASE_DE_NOMES[[#This Row],[CCT]] -> 1607 | Z8: =BASE_DE_NOMES[[#This Row],[PAGAMENTOS]]+BASE_DE_NOMES[[#This Row],[GRATIFICAÇÃO]] -> 0 | AA8: =_xlfn.XLOOKUP(BASE_DE_NOMES[[#This Row],[NOME2]],Planilha1!C:C,Planilha1!D:D)*Y8 -> 321.4 | AB8: =BASE_DE_NOMES[[#This Row],[IMPOSTOS]]+BASE_DE_NOMES[[#This Row],[SALARIO BASE]]+BASE_DE_NOMES[[#This Row],[FAMILIA]] -> 1928.4 | AC8: =_xlfn.XLOOKUP(BASE_DE_NOMES[[#This Row],[Razão Social]],Planilha1!B:B,Planilha1!C:C) -> 30 K | AD8: =_xlfn.XLOOKUP(BASE_DE_NOMES[[#This Row],[Alocações]],Planilha1!B:B,Planilha1!C:C) -> 30 K
A9: ANA PAULA JESUS DOS SANTOS | B9: COSTUREIRO (A) | C9: REIS FÁBRICA | D9: REIS FÁBRICA | E9: =IFERROR(_xlfn.XLOOKUP(BASE_DE_NOMES[[#This Row],[Nome]],'Folha Rainha'!B:B,'Folha Rainha'!D:D),0) -> 45731 | F9: =IFERROR(_xlfn.XLOOKUP(BASE_DE_NOMES[[#This Row],[Nome]],'Folha Rainha'!B:B,'Folha Rainha'!E:E)," ") -> Trabalhando | G9: =SUMIFS('Folha Rainha'!G:G,'Folha Rainha'!B:B,BASE_DE_NOMES[[#This Row],[Nome]],'Folha Rainha'!F:F,"Salário Base")+SUMIFS('Folha Rainha'!G:G,'Folha Rainha'!B:B,BASE_DE_NOMES[[#This Row],[Nome]],'Folha Rainha'!F:F,"Salário:") -> 1518 | H9: =SUMIFS('Folha Rainha'!G:G,'Folha Rainha'!B:B,BASE_DE_NOMES[[#This Row],[Nome]],'Folha Rainha'!F:F,"HORAS FALTAS PARCIAL")+SUMIFS('Folha Rainha'!G:G,'Folha Rainha'!B:B,BASE_DE_NOMES[[#This Row],[Nome]],'Folha Rainha'!F:F,"HORAS FALTAS")+SUMIFS('Folha Rainha'!G:G,'Folha Rainha'!B:B,BASE_DE_NOMES[[#This Row],[Nome]],'Folha Rainha'!F:F,"HORAS FALTAS DSR")+SUMIFS('Folha Rainha'!G:G,'Folha Rainha'!B:B,BASE_DE_NOMES[[#This Row],[Nome]],'Folha Rainha'!F:F,"FALTA DE CAIXA") -> 0 | I9: =SUMIFS('Folha Rainha'!G:G,'Folha Rainha'!B:B,BASE_DE_NOMES[[#This Row],[Nome]],'Folha Rainha'!F:F,"DESCONTO HORAS AFASTADAS")+SUMIFS('Folha Rainha'!G:G,'Folha Rainha'!B:B,BASE_DE_NOMES[[#This Row],[Nome]],'Folha Rainha'!F:F,"DESCONTO HORAS AFASTADAS ACID TRABALHO")+SUMIFS('Folha Rainha'!G:G,'Folha Rainha'!B:B,BASE_DE_NOMES[[#This Row],[Nome]],'Folha Rainha'!F:F,"SALARIO MATERNIDADE") -> 0 | J9: =BASE_DE_NOMES[[#This Row],[C.CHEQUE]]-BASE_DE_NOMES[[#This Row],[FALTAS]]-BASE_DE_NOMES[[#This Row],[DESCONTO ]] -> 1518 | K9: =SUMIF(GRATIFICAÇÃO!A:A,BASE_DE_NOMES[[#This Row],[Nome]],GRATIFICAÇÃO!F:F) -> 0 | L9: =SUMIF(PG!A:A,BASE_DE_NOMES[[#This Row],[Nome]],PG!E:E) -> 0 | M9: =SUMIFS('Folha Rainha'!G:G,'Folha Rainha'!B:B,BASE_DE_NOMES[[#This Row],[Nome]],'Folha Rainha'!F:F,"*Quebra*",'Folha Rainha'!F:F,"*QUEBRA*") -> 0 | N9: =SUMIFS('Folha Rainha'!G:G,'Folha Rainha'!B:B,BASE_DE_NOMES[[#This Row],[Nome]],'Folha Rainha'!F:F,"ADC. ANTIGUIDADE") -> 0 | O9: =SUMIFS('Folha Rainha'!G:G,'Folha Rainha'!B:B,BASE_DE_NOMES[[#This Row],[Nome]],'Folha Rainha'!F:F,"*Trienio*") -> 0 | P9: =SUMIFS('Folha Rainha'!G:G,'Folha Rainha'!B:B,BASE_DE_NOMES[[#This Row],[Nome]],'Folha Rainha'!F:F,"*TAXA*") -> 0 | Q9: =SUMIFS('Folha Rainha'!G:G,'Folha Rainha'!B:B,BASE_DE_NOMES[[#This Row],[Nome]],'Folha Rainha'!F:F,"SALARIO FAMILIA")+SUMIFS('Folha Rainha'!G:G,'Folha Rainha'!B:B,BASE_DE_NOMES[[#This Row],[Nome]],'Folha Rainha'!F:F,"Salário Família") -> 0 | R9: =SUMIFS('Folha Rainha'!G:G,'Folha Rainha'!B:B,BASE_DE_NOMES[[#This Row],[Nome]],'Folha Rainha'!F:F,"BOLSA AUXILIO")+SUMIFS('Folha Rainha'!G:G,'Folha Rainha'!B:B,BASE_DE_NOMES[[#This Row],[Nome]],'Folha Rainha'!F:F,"BOLSA AUXILIO AFASTAMENTO DIREITOS INT") -> 0 | S9: =SUMIFS('Folha Rainha'!G:G,'Folha Rainha'!B:B,BASE_DE_NOMES[[#This Row],[Nome]],'Folha Rainha'!F:F,"Vale Transporte")+SUMIFS('Folha Rainha'!G:G,'Folha Rainha'!B:B,BASE_DE_NOMES[[#This Row],[Nome]],'Folha Rainha'!F:F,"VALE TRANSPORTE 6%")+SUMIFS('Folha Rainha'!G:G,'Folha Rainha'!B:B,BASE_DE_NOMES[[#This Row],[Nome]],'Folha Rainha'!F:F,"AUXILIO TRANSPORTE ") -> 0 | T9: =SUMIFS('Folha Rainha'!G:G,'Folha Rainha'!B:B,BASE_DE_NOMES[[#This Row],[Nome]],'Folha Rainha'!F:F,"ASSISTÊNCIA ODONTOLÓGICA")+SUMIFS('Folha Rainha'!G:G,'Folha Rainha'!B:B,BASE_DE_NOMES[[#This Row],[Nome]],'Folha Rainha'!F:F,"ASSIST. ODONTO OUTROS DEPENDENTES")+SUMIFS('Folha Rainha'!G:G,'Folha Rainha'!B:B,BASE_DE_NOMES[[#This Row],[Nome]],'Folha Rainha'!F:F,"AUXILIO PLANO DE BENEFICIOS DEPENDENTES ") -> 0 | U9: =SUMIFS('Folha Rainha'!G:G,'Folha Rainha'!B:B,BASE_DE_NOMES[[#This Row],[Nome]],'Folha Rainha'!F:F,"BOLSA AUXILIO DESCONTO ADIANTAMENTO")+SUMIFS('Folha Rainha'!G:G,'Folha Rainha'!B:B,BASE_DE_NOMES[[#This Row],[Nome]],'Folha Rainha'!F:F,"DESCONTO PLANO DE SAÚDE")+BASE_DE_NOMES[[#This Row],[TX ASSIS. TOTAL]] -> 0 | V9: =BASE_DE_NOMES[[#This Row],[BOLSA DE AUXILIO]]+BASE_DE_NOMES[[#This Row],[VALE TRANSP]]+BASE_DE_NOMES[[#This Row],[PLANO DE SAUDE]]-BASE_DE_NOMES[[#This Row],[DESCONTOS]] -> 0 | W9: =SUMIFS('Folha Rainha'!G:G,'Folha Rainha'!B:B,BASE_DE_NOMES[[#This Row],[Nome]],'Folha Rainha'!F:F,"VALE COMPRAS")+SUMIFS('Folha Rainha'!G:G,'Folha Rainha'!B:B,BASE_DE_NOMES[[#This Row],[Nome]],'Folha Rainha'!F:F,"VALES") -> 0 | X9: =SUMIFS('Folha Rainha'!G:G,'Folha Rainha'!B:B,BASE_DE_NOMES[[#This Row],[Nome]],'Folha Rainha'!F:F,"ABONO CCT SECOFS 2024-2025")+SUMIFS('Folha Rainha'!G:G,'Folha Rainha'!B:B,BASE_DE_NOMES[[#This Row],[Nome]],'Folha Rainha'!F:F,"PARCELA DIFERENÇA 13o CCT")+SUMIFS('Folha Rainha'!G:G,'Folha Rainha'!B:B,BASE_DE_NOMES[[#This Row],[Nome]],'Folha Rainha'!F:F,"CONTRIBUICAO ABONO CCT 2024-2025") -> 0 | Y9: =BASE_DE_NOMES[[#This Row],[TOTAL DE C.CHEQUE]]+BASE_DE_NOMES[[#This Row],[TOTAL DE QUEBRA]]+BASE_DE_NOMES[[#This Row],[ADC. ANTIGUIDADE]]+BASE_DE_NOMES[[#This Row],[TOTAL DE TRIENIO]]+BASE_DE_NOMES[[#This Row],[CCT]] -> 1518 | Z9: =BASE_DE_NOMES[[#This Row],[PAGAMENTOS]]+BASE_DE_NOMES[[#This Row],[GRATIFICAÇÃO]] -> 0 | AA9: =_xlfn.XLOOKUP(BASE_DE_NOMES[[#This Row],[NOME2]],Planilha1!C:C,Planilha1!D:D)*Y9 -> 764.0094 | AB9: =BASE_DE_NOMES[[#This Row],[IMPOSTOS]]+BASE_DE_NOMES[[#This Row],[SALARIO BASE]]+BASE_DE_NOMES[[#This Row],[FAMILIA]] -> 2282.0094 | AC9: =_xlfn.XLOOKUP(BASE_DE_NOMES[[#This Row],[Razão Social]],Planilha1!B:B,Planilha1!C:C) -> FABRICA | AD9: =_xlfn.XLOOKUP(BASE_DE_NOMES[[#This Row],[Alocações]],Planilha1!B:B,Planilha1!C:C) -> FABRICA
